Workbook

Sheet 借款变动与利息测算
A1: 借款标识 | B1: 期初本金 | C1: 本期增加 | D1: 本期减少 | E1: 期末余额（台账） | F1: 期末余额（推算） | G1: 勾稽差异 | H1: 利率类型 | I1: 固定/执行利率 | J1: 定价基准日 | K1: LPR品种 | L1: 基准利率 | M1: 加/减点BP | N1: 有效年利率 | O1: 计息积数（元·天） | P1: 测算利息 | Q1: 匹配状态 | R1: 匹配依据 | S1: 主体 | T1: 行键（系统） | U1: 合同编号 | V1: 贷款银行 | W1: 借款金额 | X1: 起始日 | Y1: 到期日 | Z1: 执行利率（%） | AA1: 还款方式 | AB1: 借款状态 | AC1: 期末未偿还本金 | AD1: 备注 | AE1: 币种
A2: BC-001 | B2: 0 | C2: 17805000 | D2: 0 | E2: 17805000 | F2: =B2+C2-D2 -> 17805000 | G2: =IF(E2="","",B2+C2-D2-E2) -> 0 | H2: 固定 | I2: 0.0474 | M2: 0 | N2: =IF(H2="浮动",IF(ISNUMBER(L2),L2+M2/10000,0),IF(ISNUMBER(I2),I2,0)) -> 0.0474 | O2: =SUMIFS('计息分段明细'!$G:$G,'计息分段明细'!$K:$K,T2) -> 961470000 | P2: =SUMIFS('计息分段明细'!$I:$I,'计息分段明细'!$K:$K,T2) -> 124859.39 | Q2: 已匹配 | R2: 借款合同台账（合同模式）；按用户确认的台账金额及新增/还款日期分段计息（合同日期默认值可编辑，原始台账字段单独保留）；按记账日逐日加权计息 | S2: 默认主体 | T2: ledger_x001F_默认主体_x001F_bc001 | U2: BC-001 | V2: 中国银行股份有限公司深圳市分行 | W2: 17805000 | X2: 2025-11-08 00:00:00 | Y2: 2026-11-08 00:00:00 | Z2: 4.74 | AA2: 到期一次还本 | AB2: 存续 | AC2: 17805000
A3: BC-002 | B3: 0 | C3: 27060000 | D3: 0 | E3: 27060000 | F3: =B3+C3-D3 -> 27060000 | G3: =IF(E3="","",B3+C3-D3-E3) -> 0 | H3: 固定 | I3: 0.0431 | M3: 0 | N3: =IF(H3="浮动",IF(ISNUMBER(L3),L3+M3/10000,0),IF(ISNUMBER(I3),I3,0)) -> 0.0431 | O3: =SUMIFS('计息分段明细'!$G:$G,'计息分段明细'!$K:$K,T3) -> 7576800000 | P3: =SUMIFS('计息分段明细'!$I:$I,'计息分段明细'!$K:$K,T3) -> 894685.15 | Q3: 已匹配 | R3: 借款合同台账（合同模式）；按用户确认的台账金额及新增/还款日期分段计息（合同日期默认值可编辑，原始台账字段单独保留）；按记账日逐日加权计息 | S3: 默认主体 | T3: ledger_x001F_默认主体_x001F_bc002 | U3: BC-002 | V3: 中国工商银行股份有限公司深圳蛇口支行 | W3: 27060000 | X3: 2025-03-27 00:00:00 | Y3: 2026-03-27 00:00:00 | Z3: 4.31 | AA3: 到期一次还本 | AB3: 存续 | AC3: 27060000
A4: BC-003 | B4: 11160000 | C4: 0 | D4: 0 | E4: 11160000 | F4: =B4+C4-D4 -> 11160000 | G4: =IF(E4="","",B4+C4-D4-E4) -> 0 | H4: 固定 | I4: 0.0342 | M4: 0 | N4: =IF(H4="浮动",IF(ISNUMBER(L4),L4+M4/10000,0),IF(ISNUMBER(I4),I4,0)) -> 0.0342 | O4: =SUMIFS('计息分段明细'!$G:$G,'计息分段明细'!$K:$K,T4) -> 4073400000 | P4: =SUMIFS('计息分段明细'!$I:$I,'计息分段明细'!$K:$K,T4) -> 381672 | Q4: 已匹配 | R4: 借款合同台账（合同模式）；按用户确认的台账金额及新增/还款日期分段计息（合同日期默认值可编辑，原始台账字段单独保留）；本期无本金变动，按期初期末一致本金计息 | S4: 默认主体 | T4: ledger_x001F_默认主体_x001F_bc003 | U4: BC-003 | V4: 兴业银行股份有限公司北京分行 | W4: 11160000 | X4: 2024-06-27 00:00:00 | Y4: 2026-06-27 00:00:00 | Z4: 3.42 | AA4: 按季付息、到期还本 | AB4: 存续 | AC4: 11160000
A5: BC-004 | B5: 0 | C5: 15375000 | D5: 0 | E5: 15375000 | F5: =B5+C5-D5 -> 15375000 | G5: =IF(E5="","",B5+C5-D5-E5) -> 0 | H5: 固定 | I5: 0.0463 | M5: 0 | N5: =IF(H5="浮动",IF(ISNUMBER(L5),L5+M5/10000,0),IF(ISNUMBER(I5),I5,0)) -> 0.0463 | O5: =SUMIFS('计息分段明细'!$G:$G,'计息分段明细'!$K:$K,T5) -> 1537500000 | P5: =SUMIFS('计息分段明细'!$I:$I,'计息分段明细'!$K:$K,T5) -> 195030.82 | Q5: 已匹配 | R5: 借款合同台账（合同模式）；按用户确认的台账金额及新增/还款日期分段计息（合同日期默认值可编辑，原始台账字段单独保留）；按记账日逐日加权计息 | S5: 默认主体 | T5: ledger_x001F_默认主体_x001F_bc004 | U5: BC-004 | V5: 兴业银行股份有限公司北京分行 | W5: 15375000 | X5: 2025-09-23 00:00:00 | Y5: 2027-09-23 00:00:00 | Z5: 4.63 | AA5: 按季付息、到期还本 | AB5: 存续 | AC5: 15375000
A6: BC-005 | B6: 35370000 | C6: 0 | D6: 0 | E6: 35370000 | F6: =B6+C6-D6 -> 35370000 | G6: =IF(E6="","",B6+C6-D6-E6) -> 0 | H6: 固定 | I6: 0.046 | M6: 0 | N6: =IF(H6="浮动",IF(ISNUMBER(L6),L6+M6/10000,0),IF(ISNUMBER(I6),I6,0)) -> 0.046 | O6: =SUMIFS('计息分段明细'!$G:$G,'计息分段明细'!$K:$K,T6) -> 12910050000 | P6: =SUMIFS('计息分段明细'!$I:$I,'计息分段明细'!$K:$K,T6) -> 1627020 | Q6: 已匹配 | R6: 借款合同台账（合同模式）；按用户确认的台账金额及新增/还款日期分段计息（合同日期默认值可编辑，原始台账字段单独保留）；本期无本金变动，按期初期末一致本金计息 | S6: 默认主体 | T6: ledger_x001F_默认主体_x001F_bc005 | U6: BC-005 | V6: 华夏银行股份有限公司北京首体支行 | W6: 35370000 | X6: 2024-05-12 00:00:00 | Y6: 2026-11-17 00:00:00 | Z6: 4.6 | AA6: 到期一次还本 | AB6: 展期 | AC6: 35370000 | AD6: 原到期日后展期12个月
A7: BC-006 | B7: 0 | C7: 50720000 | D7: 0 | E7: 50720000 | F7: =B7+C7-D7 -> 50720000 | G7: =IF(E7="","",B7+C7-D7-E7) -> 0 | H7: 固定 | I7: 0.038 | M7: 0 | N7: =IF(H7="浮动",IF(ISNUMBER(L7),L7+M7/10000,0),IF(ISNUMBER(I7),I7,0)) -> 0.038 | O7: =SUMIFS('计息分段明细'!$G:$G,'计息分段明细'!$K:$K,T7) -> 5427040000 | P7: =SUMIFS('计息分段明细'!$I:$I,'计息分段明细'!$K:$K,T7) -> 565006.9 | Q7: 已匹配 | R7: 借款合同台账（合同模式）；按用户确认的台账金额及新增/还款日期分段计息（合同日期默认值可编辑，原始台账字段单独保留）；按记账日逐日加权计息 | S7: 默认主体 | T7: ledger_x001F_默认主体_x001F_bc006 | U7: BC-006 | V7: 平安银行股份有限公司北京分行 | W7: 50720000 | X7: 2025-09-16 00:00:00 | Y7: 2027-09-16 00:00:00 | Z7: 3.8 | AA7: 到期一次还本 | AB7: 存续 | AC7: 50720000
A8: BC-007 | B8: 42065000 | C8: 0 | D8: 0 | E8: 42065000 | F8: =B8+C8-D8 -> 42065000 | G8: =IF(E8="","",B8+C8-D8-E8) -> 0 | H8: 固定 | I8: 0.0445 | M8: 0 | N8: =IF(H8="浮动",IF(ISNUMBER(L8),L8+M8/10000,0),IF(ISNUMBER(I8),I8,0)) -> 0.0445 | O8: =SUMIFS('计息分段明细'!$G:$G,'计息分段明细'!$K:$K,T8) -> 15353725000 | P8: =SUMIFS('计息分段明细'!$I:$I,'计息分段明细'!$K:$K,T8) -> 1871892.5 | Q8: 已匹配 | R8: 借款合同台账（合同模式）；按用户确认的台账金额及新增/还款日期分段计息（合同日期默认值可编辑，原始台账字段单独保留）；本期无本金变动，按期初期末一致本金计息 | S8: 默认主体 | T8: ledger_x001F_默认主体_x001F_bc007 | U8: BC-007 | V8: 兴业银行股份有限公司北京分行 | W8: 42065000 | X8: 2024-09-09 00:00:00 | Y8: 2026-09-09 00:00:00 | Z8: 4.45 | AA8: 到期一次还本 | AB8: 存续 | AC8: 42065000
A9: BC-008 | B9: 8080000 | C9: 0 | D9: 0 | E9: 8080000 | F9: =B9+C9-D9 -> 8080000 | G9: =IF(E9="","",B9+C9-D9-E9) -> 0 | H9: 固定 | I9: 0.0433 | M9: 0 | N9: =IF(H9="浮动",IF(ISNUMBER(L9),L9+M9/10000,0),IF(ISNUMBER(I9),I9,0)) -> 0.0433 | O9: =SUMIFS('计息分段明细'!$G:$G,'计息分段明细'!$K:$K,T9) -> 2949200000 | P9: =SUMIFS('计息分段明细'!$I:$I,'计息分段明细'!$K:$K,T9) -> 349864 | Q9: 已匹配 | R9: 借款合同台账（合同模式）；按用户确认的台账金额及新增/还款日期分段计息（合同日期默认值可编辑，原始台账字段单独保留）；本期无本金变动，按期初期末一致本金计息 | S9: 默认主体 | T9: ledger_x001F_默认主体_x001F_bc008 | U9: BC-008 | V9: 招商银行股份有限公司北京分行 | W9: 8080000 | X9: 2024-06-18 00:00:00 | Y9: 2026-06-18 00:00:00 | Z9: 4.33 | AA9: 到期一次还本 | AB9: 存续 | AC9: 8080000
A10: BC-009 | B10: 0 | C10: 52495000 | D10: 0 | E10: 52495000 | F10: =B10+C10-D10 -> 52495000 | G10: =IF(E10="","",B10+C10-D10-E10) -> 0 | H10: 固定 | I10: 0.0357 | M10: 0 | N10: =IF(H10="浮动",IF(ISNUMBER(L10),L10+M10/10000,0),IF(ISNUMBER(I10),I10,0)) -> 0.0357 | O10: =SUMIFS('计息分段明细'!$G:$G,'计息分段明细'!$K:$K,T10) -> 13438720000 | P10: =SUMIFS('计息分段明细'!$I:$I,'计息分段明细'!$K:$K,T10) -> 1314417.3 | Q10: 已匹配 | R10: 借款合同台账（合同模式）；按用户确认的台账金额及新增/还款日期分段计息（合同日期默认值可编辑，原始台账字段单独保留）；按记账日逐日加权计息 | S10: 默认主体 | T10: ledger_x001F_默认主体_x001F_bc009 | U10: BC-009 | V10: 中国邮政储蓄银行股份有限公司北京海淀区支行 | W10: 52495000 | X10: 2025-04-20 00:00:00 | Y10: 2028-04-20 00:00:00 | Z10: 3.57 | AA10: 到期一次还本 | AB10: 存续 | AC10: 52495000
A11: BC-010 | B11: 0 | C11: 51635000 | D11: 51635000 | E11: 0 | F11: =B11+C11-D11 -> 0 | G11: =IF(E11="","",B11+C11-D11-E11) -> 0 | H11: 固定 | I11: 0.047 | M11: 0 | N11: =IF(H11="浮动",IF(ISNUMBER(L11),L11+M11/10000,0),IF(ISNUMBER(I11),I11,0)) -> 0.047 | O11: =SUMIFS('计息分段明细'!$G:$G,'计息分段明细'!$K:$K,T11) -> 4492245000 | P11: =SUMIFS('计息分段明细'!$I:$I,'计息分段明细'!$K:$K,T11) -> 578453.47 | Q11: 已匹配 | R11: 借款合同台账（合同模式）；按用户确认的台账金额及新增/还款日期分段计息（合同日期默认值可编辑，原始台账字段单独保留）；按记账日逐日加权计息 | S11: 默认主体 | T11: ledger_x001F_默认主体_x001F_bc010 | U11: BC-010 | V11: 上海浦东发展银行股份有限公司北京分行 | W11: 51635000 | X11: 2025-04-16 00:00:00 | Y11: 2025-07-12 00:00:00 | Z11: 4.7 | AA11: 到期一次还本 | AB11: 已结清 | AC11: 0
A12: BC-011 | B12: 52200000 | C12: 0 | D12: 0 | E12: 52200000 | F12: =B12+C12-D12 -> 52200000 | G12: =IF(E12="","",B12+C12-D12-E12) -> 0 | H12: 固定 | I12: 0.0404 | M12: 0 | N12: =IF(H12="浮动",IF(ISNUMBER(L12),L12+M12/10000,0),IF(ISNUMBER(I12),I12,0)) -> 0.0404 | O12: =SUMIFS('计息分段明细'!$G:$G,'计息分段明细'!$K:$K,T12) -> 19053000000 | P12: =SUMIFS('计息分段明细'!$I:$I,'计息分段明细'!$K:$K,T12) -> 2108880 | Q12: 已匹配 | R12: 借款合同台账（合同模式）；按用户确认的台账金额及新增/还款日期分段计息（合同日期默认值可编辑，原始台账字段单独保留）；本期无本金变动，按期初期末一致本金计息 | S12: 默认主体 | T12: ledger_x001F_默认主体_x001F_bc011 | U12: BC-011 | V12: 华夏银行股份有限公司北京首体支行 | W12: 52200000 | X12: 2024-01-07 00:00:00 | Y12: 2026-01-07 00:00:00 | Z12: 4.04 | AA12: 到期一次还本 | AB12: 存续 | AC12: 52200000
A13: BC-012 | B13: 0 | C13: 42905000 | D13: 0 | E13: 42905000 | F13: =B13+C13-D13 -> 42905000 | G13: =IF(E13="","",B13+C13-D13-E13) -> 0 | H13: 固定 | I13: 0.0349 | M13: 0 | N13: =IF(H13="浮动",IF(ISNUMBER(L13),L13+M13/10000,0),IF(ISNUMBER(I13),I13,0)) -> 0.0349 | O13: =SUMIFS('计息分段明细'!$G:$G,'计息分段明细'!$K:$K,T13) -> 12227925000 | P13: =SUMIFS('计息分段明细'!$I:$I,'计息分段明细'!$K:$K,T13) -> 1169190.6 | Q13: 已匹配 | R13: 借款合同台账（合同模式）；按用户确认的台账金额及新增/还款日期分段计息（合同日期默认值可编辑，原始台账字段单独保留）；按记账日逐日加权计息 | S13: 默认主体 | T13: ledger_x001F_默认主体_x001F_bc012 | U13: BC-012 | V13: 国家开发银行北京市分行 | W13: 42905000 | X13: 2025-03-22 00:00:00 | Y13: 2026-03-22 00:00:00 | Z13: 3.49 | AA13: 按季付息、到期还本 | AB13: 存续 | AC13: 42905000
A14: BC-013 | B14: 0 | C14: 18715000 | D14: 0 | E14: 18715000 | F14: =B14+C14-D14 -> 18715000 | G14: =IF(E14="","",B14+C14-D14-E14) -> 0 | H14: 固定 | I14: 0.0461 | M14: 0 | N14: =IF(H14="浮动",IF(ISNUMBER(L14),L14+M14/10000,0),IF(ISNUMBER(I14),I14,0)) -> 0.0461 | O14: =SUMIFS('计息分段明细'!$G:$G,'计息分段明细'!$K:$K,T14) -> 3125405000 | P14: =SUMIFS('计息分段明细'!$I:$I,'计息分段明细'!$K:$K,T14) -> 394742.93 | Q14: 已匹配 | R14: 借款合同台账（合同模式）；按用户确认的台账金额及新增/还款日期分段计息（合同日期默认值可编辑，原始台账字段单独保留）；按记账日逐日加权计息 | S14: 默认主体 | T14: ledger_x001F_默认主体_x001F_bc013 | U14: BC-013 | V14: 北京银行股份有限公司建国支行 | W14: 18715000 | X14: 2025-07-18 00:00:00 | Y14: 2026-07-18 00:00:00 | Z14: 4.61 | AA14: 到期一次还本 | AB14: 存续 | AC14: 18715000
A15: BC-014 | B15: 0 | C15: 30470000 | D15: 0 | E15: 30470000 | F15: =B15+C15-D15 -> 30470000 | G15: =IF(E15="","",B15+C15-D15-E15) -> 0 | H15: 固定 | I15: 0.0388 | M15: 0 | N15: =IF(H15="浮动",IF(ISNUMBER(L15),L15+M15/10000,0),IF(ISNUMBER(I15),I15,0)) -> 0.0388 | O15: =SUMIFS('计息分段明细'!$G:$G,'计息分段明细'!$K:$K,T15) -> 3382170000 | P15: =SUMIFS('计息分段明细'!$I:$I,'计息分段明细'!$K:$K,T15) -> 359529.3 | Q15: 已匹配 | R15: 借款合同台账（合同模式）；按用户确认的台账金额及新增/还款日期分段计息（合同日期默认值可编辑，原始台账字段单独保留）；按记账日逐日加权计息 | S15: 默认主体 | T15: ledger_x001F_默认主体_x001F_bc014 | U15: BC-014 | V15: 招商银行股份有限公司上海分行 | W15: 30470000 | X15: 2025-09-12 00:00:00 | Y15: 2026-09-12 00:00:00 | Z15: 3.88 | AA15: 按季付息、到期还本 | AB15: 存续 | AC15: 30470000
A16: BC-015 | B16: 18965000 | C16: 0 | D16: 0 | E16: 18965000 | F16: =B16+C16-D16 -> 18965000 | G16: =IF(E16="","",B16+C16-D16-E16) -> 0 | H16: 固定 | I16: 0.0387 | M16: 0 | N16: =IF(H16="浮动",IF(ISNUMBER(L16),L16+M16/10000,0),IF(ISNUMBER(I16),I16,0)) -> 0.0387 | O16: =SUMIFS('计息分段明细'!$G:$G,'计息分段明细'!$K:$K,T16) -> 6922225000 | P16: =SUMIFS('计息分段明细'!$I:$I,'计息分段明细'!$K:$K,T16) -> 733945.5 | Q16: 已匹配 | R16: 借款合同台账（合同模式）；按用户确认的台账金额及新增/还款日期分段计息（合同日期默认值可编辑，原始台账字段单独保留）；本期无本金变动，按期初期末一致本金计息 | S16: 默认主体 | T16: ledger_x001F_默认主体_x001F_bc015 | U16: BC-015 | V16: 中国银行股份有限公司北京市分行 | W16: 18965000 | X16: 2024-05-18 00:00:00 | Y16: 2026-10-11 00:00:00 | Z16: 3.87 | AA16: 按季付息、到期还本 | AB16: 展期 | AC16: 18965000 | AD16: 原到期日后展期12个月
A17: BC-016 | B17: 10910000 | C17: 0 | D17: 0 | E17: 10910000 | F17: =B17+C17-D17 -> 10910000 | G17: =IF(E17="","",B17+C17-D17-E17) -> 0 | H17: 固定 | I17: 0.0462 | M17: 0 | N17: =IF(H17="浮动",IF(ISNUMBER(L17),L17+M17/10000,0),IF(ISNUMBER(I17),I17,0)) -> 0.0462 | O17: =SUMIFS('计息分段明细'!$G:$G,'计息分段明细'!$K:$K,T17) -> 3982150000 | P17: =SUMIFS('计息分段明细'!$I:$I,'计息分段明细'!$K:$K,T17) -> 504042 | Q17: 已匹配 | R17: 借款合同台账（合同模式）；按用户确认的台账金额及新增/还款日期分段计息（合同日期默认值可编辑，原始台账字段单独保留）；本期无本金变动，按期初期末一致本金计息 | S17: 默认主体 | T17: ledger_x001F_默认主体_x001F_bc016 | U17: BC-016 | V17: 中国银行股份有限公司北京市分行 | W17: 10910000 | X17: 2024-04-16 00:00:00 | Y17: 2026-04-16 00:00:00 | Z17: 4.62 | AA17: 按季付息、到期还本 | AB17: 存续 | AC17: 10910000
A18: BC-017 | B18: 3830000 | C18: 0 | D18: 0 | E18: 3830000 | F18: =B18+C18-D18 -> 3830000 | G18: =IF(E18="","",B18+C18-D18-E18) -> 0 | H18: 固定 | I18: 0.0413 | M18: 0 | N18: =IF(H18="浮动",IF(ISNUMBER(L18),L18+M18/10000,0),IF(ISNUMBER(I18),I18,0)) -> 0.0413 | O18: =SUMIFS('计息分段明细'!$G:$G,'计息分段明细'!$K:$K,T18) -> 1397950000 | P18: =SUMIFS('计息分段明细'!$I:$I,'计息分段明细'!$K:$K,T18) -> 158179 | Q18: 已匹配 | R18: 借款合同台账（合同模式）；按用户确认的台账金额及新增/还款日期分段计息（合同日期默认值可编辑，原始台账字段单独保留）；本期无本金变动，按期初期末一致本金计息 | S18: 默认主体 | T18: ledger_x001F_默认主体_x001F_bc017 | U18: BC-017 | V18: 北京农村商业银行股份有限公司朝阳支行 | W18: 3830000 | X18: 2024-03-11 00:00:00 | Y18: 2026-03-11 00:00:00 | Z18: 4.13 | AA18: 到期一次还本 | AB18: 存续 | AC18: 3830000
A19: BC-018 | B19: 7595000 | C19: 0 | D19: 0 | E19: 7595000 | F19: =B19+C19-D19 -> 7595000 | G19: =IF(E19="","",B19+C19-D19-E19) -> 0 | H19: 固定 | I19: 0.0397 | M19: 0 | N19: =IF(H19="浮动",IF(ISNUMBER(L19),L19+M19/10000,0),IF(ISNUMBER(I19),I19,0)) -> 0.0397 | O19: =SUMIFS('计息分段明细'!$G:$G,'计息分段明细'!$K:$K,T19) -> 2772175000 | P19: =SUMIFS('计息分段明细'!$I:$I,'计息分段明细'!$K:$K,T19) -> 301521.5 | Q19: 已匹配 | R19: 借款合同台账（合同模式）；按用户确认的台账金额及新增/还款日期分段计息（合同日期默认值可编辑，原始台账字段单独保留）；本期无本金变动，按期初期末一致本金计息 | S19: 默认主体 | T19: ledger_x001F_默认主体_x001F_bc018 | U19: BC-018 | V19: 宁波银行股份有限公司北京分行 | W19: 7595000 | X19: 2024-04-24 00:00:00 | Y19: 2026-04-24 00:00:00 | Z19: 3.97 | AA19: 到期一次还本 | AB19: 存续 | AC19: 7595000
A20: BC-019 | B20: 36015000 | C20: 0 | D20: 0 | E20: 36015000 | F20: =B20+C20-D20 -> 36015000 | G20: =IF(E20="","",B20+C20-D20-E20) -> 0 | H20: 固定 | I20: 0.0366 | M20: 0 | N20: =IF(H20="浮动",IF(ISNUMBER(L20),L20+M20/10000,0),IF(ISNUMBER(I20),I20,0)) -> 0.0366 | O20: =SUMIFS('计息分段明细'!$G:$G,'计息分段明细'!$K:$K,T20) -> 13145475000 | P20: =SUMIFS('计息分段明细'!$I:$I,'计息分段明细'!$K:$K,T20) -> 1318149 | Q20: 已匹配 | R20: 借款合同台账（合同模式）；按用户确认的台账金额及新增/还款日期分段计息（合同日期默认值可编辑，原始台账字段单独保留）；本期无本金变动，按期初期末一致本金计息 | S20: 默认主体 | T20: ledger_x001F_默认主体_x001F_bc019 | U20: BC-019 | V20: 招商银行股份有限公司北京分行 | W20: 36015000 | X20: 2024-07-20 00:00:00 | Y20: 2026-07-20 00:00:00 | Z20: 3.66 | AA20: 按季付息、到期还本 | AB20: 存续 | AC20: 36015000
A21: BC-020 | B21: 0 | C21: 0 | D21: 0 | F21: =B21+C21-D21 -> 0 | G21: =IF(E21="","",B21+C21-D21-E21) -> 0 | H21: 固定 | I21: 0.0388 | M21: 0 | N21: =IF(H21="浮动",IF(ISNUMBER(L21),L21+M21/10000,0),IF(ISNUMBER(I21),I21,0)) -> 0.0388 | O21: =SUMIFS('计息分段明细'!$G:$G,'计息分段明细'!$K:$K,T21) -> 0 | P21: =SUMIFS('计息分段明细'!$I:$I,'计息分段明细'!$K:$K,T21) -> 0 | Q21: 已匹配 | R21: 借款合同台账（合同模式）；按用户确认的台账金额及新增/还款日期分段计息（合同日期默认值可编辑，原始台账字段单独保留）；本期无本金变动，按期初期末一致本金计息 | S21: 默认主体 | T21: ledger_x001F_默认主体_x001F_bc020 | U21: BC-020 | V21: 上海浦东发展银行股份有限公司北京分行 | W21: 43120000 | X21: 2023-04-06 00:00:00 | Y21: 2024-12-25 00:00:00 | Z21: 3.88 | AA21: 到期一次还本 | AB21: 已结清 | AC21: 0
A22: BC-021 | B22: 18390000 | C22: 0 | D22: 0 | E22: 18390000 | F22: =B22+C22-D22 -> 18390000 | G22: =IF(E22="","",B22+C22-D22-E22) -> 0 | H22: 固定 | I22: 0.0396 | M22: 0 | N22: =IF(H22="浮动",IF(ISNUMBER(L22),L22+M22/10000,0),IF(ISNUMBER(I22),I22,0)) -> 0.0396 | O22: =SUMIFS('计息分段明细'!$G:$G,'计息分段明细'!$K:$K,T22) -> 6712350000 | P22: =SUMIFS('计息分段明细'!$I:$I,'计息分段明细'!$K:$K,T22) -> 728244 | Q22: 已匹配 | R22: 借款合同台账（合同模式）；按用户确认的台账金额及新增/还款日期分段计息（合同日期默认值可编辑，原始台账字段单独保留）；本期无本金变动，按期初期末一致本金计息 | S22: 默认主体 | T22: ledger_x001F_默认主体_x001F_bc021 | U22: BC-021 | V22: 中国民生银行股份有限公司北京分行 | W22: 18390000 | X22: 2024-06-08 00:00:00 | Y22: 2026-06-08 00:00:00 | Z22: 3.96 | AA22: 按季付息、到期还本 | AB22: 存续 | AC22: 18390000
A23: BC-022 | B23: 32310000 | C23: 0 | D23: 0 | E23: 32310000 | F23: =B23+C23-D23 -> 32310000 | G23: =IF(E23="","",B23+C23-D23-E23) -> 0 | H23: 固定 | I23: 0.0447 | M23: 0 | N23: =IF(H23="浮动",IF(ISNUMBER(L23),L23+M23/10000,0),IF(ISNUMBER(I23),I23,0)) -> 0.0447 | O23: =SUMIFS('计息分段明细'!$G:$G,'计息分段明细'!$K:$K,T23) -> 11793150000 | P23: =SUMIFS('计息分段明细'!$I:$I,'计息分段明细'!$K:$K,T23) -> 1444257 | Q23: 已匹配 | R23: 借款合同台账（合同模式）；按用户确认的台账金额及新增/还款日期分段计息（合同日期默认值可编辑，原始台账字段单独保留）；本期无本金变动，按期初期末一致本金计息 | S23: 默认主体 | T23: ledger_x001F_默认主体_x001F_bc022 | U23: BC-022 | V23: 中国银行股份有限公司深圳市分行 | W23: 32310000 | X23: 2024-07-07 00:00:00 | Y23: 2026-07-07 00:00:00 | Z23: 4.47 | AA23: 到期一次还本 | AB23: 存续 | AC23: 32310000
A24: BC-023 | B24: 0 | C24: 42510000 | D24: 0 | E24: 42510000 | F24: =B24+C24-D24 -> 42510000 | G24: =IF(E24="","",B24+C24-D24-E24) -> 0 | H24: 固定 | I24: 0.0462 | M24: 0 | N24: =IF(H24="浮动",IF(ISNUMBER(L24),L24+M24/10000,0),IF(ISNUMBER(I24),I24,0)) -> 0.0462 | O24: =SUMIFS('计息分段明细'!$G:$G,'计息分段明细'!$K:$K,T24) -> 9309690000 | P24: =SUMIFS('计息分段明细'!$I:$I,'计息分段明细'!$K:$K,T24) -> 1178377.2 | Q24: 已匹配 | R24: 借款合同台账（合同模式）；按用户确认的台账金额及新增/还款日期分段计息（合同日期默认值可编辑，原始台账字段单独保留）；按记账日逐日加权计息 | S24: 默认主体 | T24: ledger_x001F_默认主体_x001F_bc023 | U24: BC-023 | V24: 兴业银行股份有限公司北京分行 | W24: 42510000 | X24: 2025-05-27 00:00:00 | Y24: 2026-05-27 00:00:00 | Z24: 4.62 | AA24: 按季付息、到期还本 | AB24: 存续 | AC24: 42510000
A25: BC-024 | B25: 11725000 | C25: 0 | D25: 0 | E25: 11725000 | F25: =B25+C25-D25 -> 11725000 | G25: =IF(E25="","",B25+C25-D25-E25) -> 0 | H25: 固定 | I25: 0.0465 | M25: 0 | N25: =IF(H25="浮动",IF(ISNUMBER(L25),L25+M25/10000,0),IF(ISNUMBER(I25),I25,0)) -> 0.0465 | O25: =SUMIFS('计息分段明细'!$G:$G,'计息分段明细'!$K:$K,T25) -> 4279625000 | P25: =SUMIFS('计息分段明细'!$I:$I,'计息分段明细'!$K:$K,T25) -> 545212.5 | Q25: 已匹配 | R25: 借款合同台账（合同模式）；按用户确认的台账金额及新增/还款日期分段计息（合同日期默认值可编辑，原始台账字段单独保留）；本期无本金变动，按期初期末一致本金计息 | S25: 默认主体 | T25: ledger_x001F_默认主体_x001F_bc024 | U25: BC-024 | V25: 中国进出口银行北京分行 | W25: 11725000 | X25: 2024-06-05 00:00:00 | Y25: 2027-06-05 00:00:00 | Z25: 4.65 | AA25: 按季付息、到期还本 | AB25: 存续 | AC25: 11725000
A26: BC-025 | B26: 50660000 | C26: 0 | D26: 0 | E26: 50660000 | F26: =B26+C26-D26 -> 50660000 | G26: =IF(E26="","",B26+C26-D26-E26) -> 0 | H26: 固定 | I26: 0.0402 | M26: 0 | N26: =IF(H26="浮动",IF(ISNUMBER(L26),L26+M26/10000,0),IF(ISNUMBER(I26),I26,0)) -> 0.0402 | O26: =SUMIFS('计息分段明细'!$G:$G,'计息分段明细'!$K:$K,T26) -> 18490900000 | P26: =SUMIFS('计息分段明细'!$I:$I,'计息分段明细'!$K:$K,T26) -> 2036532 | Q26: 已匹配 | R26: 借款合同台账（合同模式）；按用户确认的台账金额及新增/还款日期分段计息（合同日期默认值可编辑，原始台账字段单独保留）；本期无本金变动，按期初期末一致本金计息 | S26: 默认主体 | T26: ledger_x001F_默认主体_x001F_bc025 | U26: BC-025 | V26: 中国进出口银行北京分行 | W26: 50660000 | X26: 2024-10-25 00:00:00 | Y26: 2026-01-01 00:00:00 | Z26: 4.02 | AA26: 按季付息、到期还本 | AB26: 展期 | AC26: 50660000 | AD26: 原到期日后展期12个月
A27: BC-026 | B27: 50340000 | C27: 0 | D27: 0 | E27: 50340000 | F27: =B27+C27-D27 -> 50340000 | G27: =IF(E27="","",B27+C27-D27-E27) -> 0 | H27: 固定 | I27: 0.045 | M27: 0 | N27: =IF(H27="浮动",IF(ISNUMBER(L27),L27+M27/10000,0),IF(ISNUMBER(I27),I27,0)) -> 0.045 | O27: =SUMIFS('计息分段明细'!$G:$G,'计息分段明细'!$K:$K,T27) -> 18374100000 | P27: =SUMIFS('计息分段明细'!$I:$I,'计息分段明细'!$K:$K,T27) -> 2265300 | Q27: 已匹配 | R27: 借款合同台账（合同模式）；按用户确认的台账金额及新增/还款日期分段计息（合同日期默认值可编辑，原始台账字段单独保留）；本期无本金变动，按期初期末一致本金计息 | S27: 默认主体 | T27: ledger_x001F_默认主体_x001F_bc026 | U27: BC-026 | V27: 上海浦东发展银行股份有限公司北京分行 | W27: 50340000 | X27: 2024-07-18 00:00:00 | Y27: 2026-07-18 00:00:00 | Z27: 4.5 | AA27: 按季付息、到期还本 | AB27: 存续 | AC27: 50340000
A28: BC-027 | B28: 34145000 | C28: 0 | D28: 0 | E28: 34145000 | F28: =B28+C28-D28 -> 34145000 | G28: =IF(E28="","",B28+C28-D28-E28) -> 0 | H28: 固定 | I28: 0.042 | M28: 0 | N28: =IF(H28="浮动",IF(ISNUMBER(L28),L28+M28/10000,0),IF(ISNUMBER(I28),I28,0)) -> 0.042 | O28: =SUMIFS('计息分段明细'!$G:$G,'计息分段明细'!$K:$K,T28) -> 12462925000 | P28: =SUMIFS('计息分段明细'!$I:$I,'计息分段明细'!$K:$K,T28) -> 1434090 | Q28: 已匹配 | R28: 借款合同台账（合同模式）；按用户确认的台账金额及新增/还款日期分段计息（合同日期默认值可编辑，原始台账字段单独保留）；本期无本金变动，按期初期末一致本金计息 | S28: 默认主体 | T28: ledger_x001F_默认主体_x001F_bc027 | U28: BC-027 | V28: 国家开发银行北京市分行 | W28: 34145000 | X28: 2024-07-02 00:00:00 | Y28: 2026-07-02 00:00:00 | Z28: 4.2 | AA28: 按季付息、到期还本 | AB28: 存续 | AC28: 34145000
A29: BC-028 | B29: 32270000 | C29: 0 | D29: 0 | E29: 32270000 | F29: =B29+C29-D29 -> 32270000 | G29: =IF(E29="","",B29+C29-D29-E29) -> 0 | H29: 固定 | I29: 0.0398 | M29: 0 | N29: =IF(H29="浮动",IF(ISNUMBER(L29),L29+M29/10000,0),IF(ISNUMBER(I29),I29,0)) -> 0.0398 | O29: =SUMIFS('计息分段明细'!$G:$G,'计息分段明细'!$K:$K,T29) -> 11778550000 | P29: =SUMIFS('计息分段明细'!$I:$I,'计息分段明细'!$K:$K,T29) -> 1284346 | Q29: 已匹配 | R29: 借款合同台账（合同模式）；按用户确认的台账金额及新增/还款日期分段计息（合同日期默认值可编辑，原始台账字段单独保留）；本期无本金变动，按期初期末一致本金计息 | S29: 默认主体 | T29: ledger_x001F_默认主体_x001F_bc028 | U29: BC-028 | V29: 中国工商银行股份有限公司深圳蛇口支行 | W29: 32270000 | X29: 2024-04-25 00:00:00 | Y29: 2026-04-25 00:00:00 | Z29: 3.98 | AA29: 按季付息、到期还本 | AB29: 存续 | AC29: 32270000
A30: BC-029 | B30: 50315000 | C30: 0 | D30: 0 | E30: 50315000 | F30: =B30+C30-D30 -> 50315000 | G30: =IF(E30="","",B30+C30-D30-E30) -> 0 | H30: 固定 | I30: 0.0392 | M30: 0 | N30: =IF(H30="浮动",IF(ISNUMBER(L30),L30+M30/10000,0),IF(ISNUMBER(I30),I30,0)) -> 0.0392 | O30: =SUMIFS('计息分段明细'!$G:$G,'计息分段明细'!$K:$K,T30) -> 18364975000 | P30: =SUMIFS('计息分段明细'!$I:$I,'计息分段明细'!$K:$K,T30) -> 1972348 | Q30: 已匹配 | R30: 借款合同台账（合同模式）；按用户确认的台账金额及新增/还款日期分段计息（合同日期默认值可编辑，原始台账字段单独保留）；本期无本金变动，按期初期末一致本金计息 | S30: 默认主体 | T30: ledger_x001F_默认主体_x001F_bc029 | U30: BC-029 | V30: 中国银行股份有限公司北京市分行 | W30: 50315000 | X30: 2024-08-10 00:00:00 | Y30: 2027-08-10 00:00:00 | Z30: 3.92 | AA30: 按季付息、到期还本 | AB30: 存续 | AC30: 50315000
A31: BC-030 | B31: 0 | C31: 35315000 | D31: 35315000 | E31: 0 | F31: =B31+C31-D31 -> 0 | G31: =IF(E31="","",B31+C31-D31-E31) -> 0 | H31: 固定 | I31: 0.038 | M31: 0 | N31: =IF(H31="浮动",IF(ISNUMBER(L31),L31+M31/10000,0),IF(ISNUMBER(I31),I31,0)) -> 0.038 | O31: =SUMIFS('计息分段明细'!$G:$G,'计息分段明细'!$K:$K,T31) -> 8864065000 | P31: =SUMIFS('计息分段明细'!$I:$I,'计息分段明细'!$K:$K,T31) -> 922834.16 | Q31: 已匹配 | R31: 借款合同台账（合同模式）；按用户确认的台账金额及新增/还款日期分段计息（合同日期默认值可编辑，原始台账字段单独保留）；按记账日逐日加权计息 | S31: 默认主体 | T31: ledger_x001F_默认主体_x001F_bc030 | U31: BC-030 | V31: 北京银行股份有限公司建国支行 | W31: 35315000 | X31: 2025-01-08 00:00:00 | Y31: 2025-09-16 00:00:00 | Z31: 3.8 | AA31: 按季付息、到期还本 | AB31: 已结清 | AC31: 0
A32: BC-031 | B32: 20565000 | C32: 0 | D32: 0 | E32: 20565000 | F32: =B32+C32-D32 -> 20565000 | G32: =IF(E32="","",B32+C32-D32-E32) -> 0 | H32: 固定 | I32: 0.0338 | M32: 0 | N32: =IF(H32="浮动",IF(ISNUMBER(L32),L32+M32/10000,0),IF(ISNUMBER(I32),I32,0)) -> 0.0338 | O32: =SUMIFS('计息分段明细'!$G:$G,'计息分段明细'!$K:$K,T32) -> 7506225000 | P32: =SUMIFS('计息分段明细'!$I:$I,'计息分段明细'!$K:$K,T32) -> 695097 | Q32: 已匹配 | R32: 借款合同台账（合同模式）；按用户确认的台账金额及新增/还款日期分段计息（合同日期默认值可编辑，原始台账字段单独保留）；本期无本金变动，按期初期末一致本金计息 | S32: 默认主体 | T32: ledger_x001F_默认主体_x001F_bc031 | U32: BC-031 | V32: 平安银行股份有限公司北京分行 | W32: 20565000 | X32: 2024-12-25 00:00:00 | Y32: 2027-12-25 00:00:00 | Z32: 3.38 | AA32: 到期一次还本 | AB32: 存续 | AC32: 20565000
A33: BC-032 | B33: 30175000 | C33: 0 | D33: 0 | E33: 30175000 | F33: =B33+C33-D33 -> 30175000 | G33: =IF(E33="","",B33+C33-D33-E33) -> 0 | H33: 固定 | I33: 0.0398 | M33: 0 | N33: =IF(H33="浮动",IF(ISNUMBER(L33),L33+M33/10000,0),IF(ISNUMBER(I33),I33,0)) -> 0.0398 | O33: =SUMIFS('计息分段明细'!$G:$G,'计息分段明细'!$K:$K,T33) -> 11013875000 | P33: =SUMIFS('计息分段明细'!$I:$I,'计息分段明细'!$K:$K,T33) -> 1200965 | Q33: 已匹配 | R33: 借款合同台账（合同模式）；按用户确认的台账金额及新增/还款日期分段计息（合同日期默认值可编辑，原始台账字段单独保留）；本期无本金变动，按期初期末一致本金计息 | S33: 默认主体 | T33: ledger_x001F_默认主体_x001F_bc032 | U33: BC-032 | V33: 中国工商银行股份有限公司北京朝阳支行 | W33: 30175000 | X33: 2024-06-11 00:00:00 | Y33: 2027-06-11 00:00:00 | Z33: 3.98 | AA33: 按季付息、到期还本 | AB33: 存续 | AC33: 30175000
A34: 合计 | B34: =SUM(B2:B33) -> 557085000 | C34: =SUM(C2:C33) -> 385005000 | D34: =SUM(D2:D33) -> 86950000 | E34: =SUM(E2:E33) -> 855140000 | F34: =SUM(F2:F33) -> 855140000 | G34: =SUM(G2:G33) -> 0 | O34: =SUM(O2:O33) -> 273679055000 | P34: =SUM(P2:P33) -> 30658684
A36: 测算与账面利息对比
A37: 项目 | B37: 金额 | C37: 说明
A38: 测算利息支出 | B38: =P34 -> 30658684 | C38: 本金×利率×计息天数÷365；计息过程见「计息分段明细」
A39: 账面利息支出（TB 利息科目） | C39: 未选择利息支出科目，未做账面对比（TB＋JE 模式第二步勾选利息支出科目后可对比）
A40: 差异（测算－账面） | B40: =IF(ISNUMBER(B39),B38-B39,"") -> 0 | C40: 差异为正表示测算大于账面
A42: 利率填写：固定选“固定”，仅填黄色固定利率；浮动选“浮动”，填写蓝色基准利率和加减点。365为年利率折算基数，不是每笔计息天数；每次本金增减对应的实际天数请见“计息分段明细”。

Sheet 计息分段明细
A1: 借款标识 | B1: 段号 | C1: 起日 | D1: 止日（含当天） | E1: 计息本金 | F1: 天数 | G1: 积数（本金×天） | H1: 适用年利率 | I1: 段利息 | J1: 主体 | K1: 行键（系统）
A2: BC-001 | B2: 1 | C2: 45658 | D2: 45968 | E2: 0 | F2: =D2-C2+1 -> 311 | G2: =E2*F2 -> 0 | H2: ='借款变动与利息测算'!N2 -> 0.0474 | I2: =E2*H2*F2/365 -> 0 | J2: 默认主体 | K2: ledger_x001F_默认主体_x001F_bc001
A3: BC-001 | B3: 2 | C3: 45969 | D3: 46022 | E3: 17805000 | F3: =D3-C3+1 -> 54 | G3: =E3*F3 -> 961470000 | H3: ='借款变动与利息测算'!N2 -> 0.0474 | I3: =E3*H3*F3/365 -> 124859.39 | J3: 默认主体 | K3: ledger_x001F_默认主体_x001F_bc001
A4: BC-002 | B4: 1 | C4: 45658 | D4: 45742 | E4: 0 | F4: =D4-C4+1 -> 85 | G4: =E4*F4 -> 0 | H4: ='借款变动与利息测算'!N3 -> 0.0431 | I4: =E4*H4*F4/365 -> 0 | J4: 默认主体 | K4: ledger_x001F_默认主体_x001F_bc002
A5: BC-002 | B5: 2 | C5: 45743 | D5: 46022 | E5: 27060000 | F5: =D5-C5+1 -> 280 | G5: =E5*F5 -> 7576800000 | H5: ='借款变动与利息测算'!N3 -> 0.0431 | I5: =E5*H5*F5/365 -> 894685.15 | J5: 默认主体 | K5: ledger_x001F_默认主体_x001F_bc002
A6: BC-003 | B6: 1 | C6: 45658 | D6: 46022 | E6: 11160000 | F6: =D6-C6+1 -> 365 | G6: =E6*F6 -> 4073400000 | H6: ='借款变动与利息测算'!N4 -> 0.0342 | I6: =E6*H6*F6/365 -> 381672 | J6: 默认主体 | K6: ledger_x001F_默认主体_x001F_bc003
A7: BC-004 | B7: 1 | C7: 45658 | D7: 45922 | E7: 0 | F7: =D7-C7+1 -> 265 | G7: =E7*F7 -> 0 | H7: ='借款变动与利息测算'!N5 -> 0.0463 | I7: =E7*H7*F7/365 -> 0 | J7: 默认主体 | K7: ledger_x001F_默认主体_x001F_bc004
A8: BC-004 | B8: 2 | C8: 45923 | D8: 46022 | E8: 15375000 | F8: =D8-C8+1 -> 100 | G8: =E8*F8 -> 1537500000 | H8: ='借款变动与利息测算'!N5 -> 0.0463 | I8: =E8*H8*F8/365 -> 195030.82 | J8: 默认主体 | K8: ledger_x001F_默认主体_x001F_bc004
A9: BC-005 | B9: 1 | C9: 45658 | D9: 46022 | E9: 35370000 | F9: =D9-C9+1 -> 365 | G9: =E9*F9 -> 12910050000 | H9: ='借款变动与利息测算'!N6 -> 0.046 | I9: =E9*H9*F9/365 -> 1627020 | J9: 默认主体 | K9: ledger_x001F_默认主体_x001F_bc005
A10: BC-006 | B10: 1 | C10: 45658 | D10: 45915 | E10: 0 | F10: =D10-C10+1 -> 258 | G10: =E10*F10 -> 0 | H10: ='借款变动与利息测算'!N7 -> 0.038 | I10: =E10*H10*F10/365 -> 0 | J10: 默认主体 | K10: ledger_x001F_默认主体_x001F_bc006
A11: BC-006 | B11: 2 | C11: 45916 | D11: 46022 | E11: 50720000 | F11: =D11-C11+1 -> 107 | G11: =E11*F11 -> 5427040000 | H11: ='借款变动与利息测算'!N7 -> 0.038 | I11: =E11*H11*F11/365 -> 565006.9 | J11: 默认主体 | K11: ledger_x001F_默认主体_x001F_bc006
A12: BC-007 | B12: 1 | C12: 45658 | D12: 46022 | E12: 42065000 | F12: =D12-C12+1 -> 365 | G12: =E12*F12 -> 15353725000 | H12: ='借款变动与利息测算'!N8 -> 0.0445 | I12: =E12*H12*F12/365 -> 1871892.5 | J12: 默认主体 | K12: ledger_x001F_默认主体_x001F_bc007
A13: BC-008 | B13: 1 | C13: 45658 | D13: 46022 | E13: 8080000 | F13: =D13-C13+1 -> 365 | G13: =E13*F13 -> 2949200000 | H13: ='借款变动与利息测算'!N9 -> 0.0433 | I13: =E13*H13*F13/365 -> 349864 | J13: 默认主体 | K13: ledger_x001F_默认主体_x001F_bc008
A14: BC-009 | B14: 1 | C14: 45658 | D14: 45766 | E14: 0 | F14: =D14-C14+1 -> 109 | G14: =E14*F14 -> 0 | H14: ='借款变动与利息测算'!N10 -> 0.0357 | I14: =E14*H14*F14/365 -> 0 | J14: 默认主体 | K14: ledger_x001F_默认主体_x001F_bc009
A15: BC-009 | B15: 2 | C15: 45767 | D15: 46022 | E15: 52495000 | F15: =D15-C15+1 -> 256 | G15: =E15*F15 -> 13438720000 | H15: ='借款变动与利息测算'!N10 -> 0.0357 | I15: =E15*H15*F15/365 -> 1314417.3 | J15: 默认主体 | K15: ledger_x001F_默认主体_x001F_bc009
A16: BC-010 | B16: 1 | C16: 45658 | D16: 45762 | E16: 0 | F16: =D16-C16+1 -> 105 | G16: =E16*F16 -> 0 | H16: ='借款变动与利息测算'!N11 -> 0.047 | I16: =E16*H16*F16/365 -> 0 | J16: 默认主体 | K16: ledger_x001F_默认主体_x001F_bc010
A17: BC-010 | B17: 2 | C17: 45763 | D17: 45849 | E17: 51635000 | F17: =D17-C17+1 -> 87 | G17: =E17*F17 -> 4492245000 | H17: ='借款变动与利息测算'!N11 -> 0.047 | I17: =E17*H17*F17/365 -> 578453.47 | J17: 默认主体 | K17: ledger_x001F_默认主体_x001F_bc010
A18: BC-010 | B18: 3 | C18: 45850 | D18: 46022 | E18: 0 | F18: =D18-C18+1 -> 173 | G18: =E18*F18 -> 0 | H18: ='借款变动与利息测算'!N11 -> 0.047 | I18: =E18*H18*F18/365 -> 0 | J18: 默认主体 | K18: ledger_x001F_默认主体_x001F_bc010
A19: BC-011 | B19: 1 | C19: 45658 | D19: 46022 | E19: 52200000 | F19: =D19-C19+1 -> 365 | G19: =E19*F19 -> 19053000000 | H19: ='借款变动与利息测算'!N12 -> 0.0404 | I19: =E19*H19*F19/365 -> 2108880 | J19: 默认主体 | K19: ledger_x001F_默认主体_x001F_bc011
A20: BC-012 | B20: 1 | C20: 45658 | D20: 45737 | E20: 0 | F20: =D20-C20+1 -> 80 | G20: =E20*F20 -> 0 | H20: ='借款变动与利息测算'!N13 -> 0.0349 | I20: =E20*H20*F20/365 -> 0 | J20: 默认主体 | K20: ledger_x001F_默认主体_x001F_bc012
A21: BC-012 | B21: 2 | C21: 45738 | D21: 46022 | E21: 42905000 | F21: =D21-C21+1 -> 285 | G21: =E21*F21 -> 12227925000 | H21: ='借款变动与利息测算'!N13 -> 0.0349 | I21: =E21*H21*F21/365 -> 1169190.6 | J21: 默认主体 | K21: ledger_x001F_默认主体_x001F_bc012
A22: BC-013 | B22: 1 | C22: 45658 | D22: 45855 | E22: 0 | F22: =D22-C22+1 -> 198 | G22: =E22*F22 -> 0 | H22: ='借款变动与利息测算'!N14 -> 0.0461 | I22: =E22*H22*F22/365 -> 0 | J22: 默认主体 | K22: ledger_x001F_默认主体_x001F_bc013
A23: BC-013 | B23: 2 | C23: 45856 | D23: 46022 | E23: 18715000 | F23: =D23-C23+1 -> 167 | G23: =E23*F23 -> 3125405000 | H23: ='借款变动与利息测算'!N14 -> 0.0461 | I23: =E23*H23*F23/365 -> 394742.93 | J23: 默认主体 | K23: ledger_x001F_默认主体_x001F_bc013
A24: BC-014 | B24: 1 | C24: 45658 | D24: 45911 | E24: 0 | F24: =D24-C24+1 -> 254 | G24: =E24*F24 -> 0 | H24: ='借款变动与利息测算'!N15 -> 0.0388 | I24: =E24*H24*F24/365 -> 0 | J24: 默认主体 | K24: ledger_x001F_默认主体_x001F_bc014
A25: BC-014 | B25: 2 | C25: 45912 | D25: 46022 | E25: 30470000 | F25: =D25-C25+1 -> 111 | G25: =E25*F25 -> 3382170000 | H25: ='借款变动与利息测算'!N15 -> 0.0388 | I25: =E25*H25*F25/365 -> 359529.3 | J25: 默认主体 | K25: ledger_x001F_默认主体_x001F_bc014
A26: BC-015 | B26: 1 | C26: 45658 | D26: 46022 | E26: 18965000 | F26: =D26-C26+1 -> 365 | G26: =E26*F26 -> 6922225000 | H26: ='借款变动与利息测算'!N16 -> 0.0387 | I26: =E26*H26*F26/365 -> 733945.5 | J26: 默认主体 | K26: ledger_x001F_默认主体_x001F_bc015
A27: BC-016 | B27: 1 | C27: 45658 | D27: 46022 | E27: 10910000 | F27: =D27-C27+1 -> 365 | G27: =E27*F27 -> 3982150000 | H27: ='借款变动与利息测算'!N17 -> 0.0462 | I27: =E27*H27*F27/365 -> 504042 | J27: 默认主体 | K27: ledger_x001F_默认主体_x001F_bc016
A28: BC-017 | B28: 1 | C28: 45658 | D28: 46022 | E28: 3830000 | F28: =D28-C28+1 -> 365 | G28: =E28*F28 -> 1397950000 | H28: ='借款变动与利息测算'!N18 -> 0.0413 | I28: =E28*H28*F28/365 -> 158179 | J28: 默认主体 | K28: ledger_x001F_默认主体_x001F_bc017
A29: BC-018 | B29: 1 | C29: 45658 | D29: 46022 | E29: 7595000 | F29: =D29-C29+1 -> 365 | G29: =E29*F29 -> 2772175000 | H29: ='借款变动与利息测算'!N19 -> 0.0397 | I29: =E29*H29*F29/365 -> 301521.5 | J29: 默认主体 | K29: ledger_x001F_默认主体_x001F_bc018
A30: BC-019 | B30: 1 | C30: 45658 | D30: 46022 | E30: 36015000 | F30: =D30-C30+1 -> 365 | G30: =E30*F30 -> 13145475000 | H30: ='借款变动与利息测算'!N20 -> 0.0366 | I30: =E30*H30*F30/365 -> 1318149 | J30: 默认主体 | K30: ledger_x001F_默认主体_x001F_bc019
A31: BC-020 | B31: 1 | C31: 45658 | D31: 46022 | E31: 0 | F31: =D31-C31+1 -> 365 | G31: =E31*F31 -> 0 | H31: ='借款变动与利息测算'!N21 -> 0.0388 | I31: =E31*H31*F31/365 -> 0 | J31: 默认主体 | K31: ledger_x001F_默认主体_x001F_bc020
A32: BC-021 | B32: 1 | C32: 45658 | D32: 46022 | E32: 18390000 | F32: =D32-C32+1 -> 365 | G32: =E32*F32 -> 6712350000 | H32: ='借款变动与利息测算'!N22 -> 0.0396 | I32: =E32*H32*F32/365 -> 728244 | J32: 默认主体 | K32: ledger_x001F_默认主体_x001F_bc021
A33: BC-022 | B33: 1 | C33: 45658 | D33: 46022 | E33: 32310000 | F33: =D33-C33+1 -> 365 | G33: =E33*F33 -> 11793150000 | H33: ='借款变动与利息测算'!N23 -> 0.0447 | I33: =E33*H33*F33/365 -> 1444257 | J33: 默认主体 | K33: ledger_x001F_默认主体_x001F_bc022
A34: BC-023 | B34: 1 | C34: 45658 | D34: 45803 | E34: 0 | F34: =D34-C34+1 -> 146 | G34: =E34*F34 -> 0 | H34: ='借款变动与利息测算'!N24 -> 0.0462 | I34: =E34*H34*F34/365 -> 0 | J34: 默认主体 | K34: ledger_x001F_默认主体_x001F_bc023
A35: BC-023 | B35: 2 | C35: 45804 | D35: 46022 | E35: 42510000 | F35: =D35-C35+1 -> 219 | G35: =E35*F35 -> 9309690000 | H35: ='借款变动与利息测算'!N24 -> 0.0462 | I35: =E35*H35*F35/365 -> 1178377.2 | J35: 默认主体 | K35: ledger_x001F_默认主体_x001F_bc023
A36: BC-024 | B36: 1 | C36: 45658 | D36: 46022 | E36: 11725000 | F36: =D36-C36+1 -> 365 | G36: =E36*F36 -> 4279625000 | H36: ='借款变动与利息测算'!N25 -> 0.0465 | I36: =E36*H36*F36/365 -> 545212.5 | J36: 默认主体 | K36: ledger_x001F_默认主体_x001F_bc024
A37: BC-025 | B37: 1 | C37: 45658 | D37: 46022 | E37: 50660000 | F37: =D37-C37+1 -> 365 | G37: =E37*F37 -> 18490900000 | H37: ='借款变动与利息测算'!N26 -> 0.0402 | I37: =E37*H37*F37/365 -> 2036532 | J37: 默认主体 | K37: ledger_x001F_默认主体_x001F_bc025
A38: BC-026 | B38: 1 | C38: 45658 | D38: 46022 | E38: 50340000 | F38: =D38-C38+1 -> 365 | G38: =E38*F38 -> 18374100000 | H38: ='借款变动与利息测算'!N27 -> 0.045 | I38: =E38*H38*F38/365 -> 2265300 | J38: 默认主体 | K38: ledger_x001F_默认主体_x001F_bc026
A39: BC-027 | B39: 1 | C39: 45658 | D39: 46022 | E39: 34145000 | F39: =D39-C39+1 -> 365 | G39: =E39*F39 -> 12462925000 | H39: ='借款变动与利息测算'!N28 -> 0.042 | I39: =E39*H39*F39/365 -> 1434090 | J39: 默认主体 | K39: ledger_x001F_默认主体_x001F_bc027
A40: BC-028 | B40: 1 | C40: 45658 | D40: 46022 | E40: 32270000 | F40: =D40-C40+1 -> 365 | G40: =E40*F40 -> 11778550000 | H40: ='借款变动与利息测算'!N29 -> 0.0398 | I40: =E40*H40*F40/365 -> 1284346 | J40: 默认主体 | K40: ledger_x001F_默认主体_x001F_bc028
...

Sheet LPR报价表
A1: 贷款市场报价利率（LPR）
A2: 数据截至 2026-08-20。本表只列利率发生调整的日期；LPR 每月 20 日报价，未调整的月份沿用上一次报价。
A3: 来源（可点击）： | B3: 历史月度报价 | C3: 最新公告 | D3: 2026-08-28 核验。正式出具前请核对合同重定价约定；补录报价时按日期升序插入整行并核对公式引用范围。
A4: 利率调整生效日 | B4: 1年期LPR(%) | C4: 5年期以上LPR(%)
A5: 43697 | B5: 4.25 | C5: 4.85
A6: 43728 | B6: 4.2 | C6: 4.85
A7: 43789 | B7: 4.15 | C7: 4.8
A8: 43881 | B8: 4.05 | C8: 4.75
A9: 43941 | B9: 3.85 | C9: 4.65
A10: 44550 | B10: 3.8 | C10: 4.65
A11: 44581 | B11: 3.7 | C11: 4.6
A12: 44701 | B12: 3.7 | C12: 4.45
A13: 44795 | B13: 3.65 | C13: 4.3
A14: 45097 | B14: 3.55 | C14: 4.2
A15: 45159 | B15: 3.45 | C15: 4.2
A16: 45342 | B16: 3.45 | C16: 3.95
... A19: 45797 | B19: 3 | C19: 3.5
