Workbook

Sheet 审计结论
A1: 项目 | B1: 结果
A2: 公司/核算主体 | B2: 默认主体
A3: 报告期间 | B3: 2026-01-01 至 2026-06-30
A4: 测算范围 | B4: 已实现＋未实现
A5: 各公司按本位币分别比较；不同本位币不汇总。
A7: 公司 | B7: 记账本位币 | C7: 已实现审计测算 | D7: 未实现审计测算 | E7: 审计合计 | F7: 客户账面合计（JE） | G7: 差异 | H7: 结论
A8: SZ01 | B8: CNY | C8: 0 | D8: =SUMIFS('未实现月度测算'!$J$2:$J$97,'未实现月度测算'!$A$2:$A$97,A8,'未实现月度测算'!$K$2:$K$97,B8) -> 76664.21 | E8: =C8+D8 -> 76664.21 | F8: =SUMIFS($E$13:$E$14,$A$13:$A$14,A8,$B$13:$B$14,B8) -> -19025.97 | G8: =E8-F8 -> 95690.18 | H8: =IF(OR(NOT(ISNUMBER(F8)),NOT(ISNUMBER(G8))),"无法判断",IF(ABS(F8)<0.01,"无法判断",IF(ABS(G8/F8)<0.05,"通过","不通过"))) -> 不通过
A9: US01 | B9: USD | C9: 0 | D9: =SUMIFS('未实现月度测算'!$J$2:$J$97,'未实现月度测算'!$A$2:$A$97,A9,'未实现月度测算'!$K$2:$K$97,B9) -> 732.50203 | E9: =C9+D9 -> 732.50203 | F9: =SUMIFS($E$13:$E$14,$A$13:$A$14,A9,$B$13:$B$14,B9) -> -364 | G9: =E9-F9 -> 1096.502 | H9: =IF(OR(NOT(ISNUMBER(F9)),NOT(ISNUMBER(G9))),"无法判断",IF(ABS(F9)<0.01,"无法判断",IF(ABS(G9/F9)<0.05,"通过","不通过"))) -> 不通过
A11: 客户账面汇兑损益来源
A12: 主体 | B12: 本位币 | C12: JE源行 | D12: 汇兑损益科目 | E12: 客户账面金额 | F12: 日期 | G12: 凭证号
A13: SZ01 | B13: CNY | C13: 172 | D13: 财务费用-汇兑损益 | E13: -19025.97 | F13: 2026-06-30 | G13: SZ01-2026-06-30-FXREVAL-0630
A14: US01 | B14: USD | C14: 281 | D14: 财务费用-汇兑损益 | E14: -364 | F14: 2026-06-30 | G14: US01-2026-06-30-FXREVAL-0630
A16: 待复核凭证
A17: 凭证号 | B17: 日期 | C17: 分类 | D17: 账面汇差 | E17: 原因
A18: SZ01-2026-06-30-FXREVAL-0630 | B18: 2026-06-30 | C18: 不构成汇兑事项 | D18: -19025.97 | E18: 凭证未满足 A/B/C 已实现收付结构，也不满足原币无实际发生的未实现结构；账面汇差已从测算总体剔除
A19: US01-2026-06-30-FXREVAL-0630 | B19: 2026-06-30 | C19: 不构成汇兑事项 | D19: -364 | E19: 凭证未满足 A/B/C 已实现收付结构，也不满足原币无实际发生的未实现结构；账面汇差已从测算总体剔除
A21: 凭证分类复核
A22: 凭证号 | B22: 日期 | C22: 分类 | D22: 账面汇差 | E22: 状态 | F22: 原因
A23: SZ01-2026-06-30-FXREVAL-0630 | B23: 2026-06-30 | C23: 不构成汇兑事项 | D23: -19025.97 | E23: 不构成汇兑事项，账面汇差已剔除 | F23: 凭证未满足 A/B/C 已实现收付结构，也不满足原币无实际发生的未实现结构；账面汇差已从测算总体剔除
A24: US01-2026-06-30-FXREVAL-0630 | B24: 2026-06-30 | C24: 不构成汇兑事项 | D24: -364 | E24: 不构成汇兑事项，账面汇差已剔除 | F24: 凭证未满足 A/B/C 已实现收付结构，也不满足原币无实际发生的未实现结构；账面汇差已从测算总体剔除

Sheet 未实现月度测算
A1: 主体 | B1: 科目 | C1: 币种（原币→本位币） | D1: 月末 | E1: 期初审计余额 | F1: 本月审计发生额 | G1: 月末原币余额 | H1: 月末审计汇率 | I1: 审计月末余额 | J1: 未实现汇差
A2: SZ01 | B2: 01.13010.0000.0000.0000 其他应收款 | C2: USD→CNY | D2: 2026-01-31 | E2: 35600 | F2: 0 | G2: 5000 | H2: =INDEX('汇率表'!$A:$XFD,MATCH(D2,'汇率表'!$A:$A,0),MATCH(L2,'汇率表'!$1:$1,0)) -> 6.9678 | I2: =G2*H2 -> 34839 | J2: =E2+F2-I2 -> 761 | K2: CNY | L2: USD | M2: 5000
A3: SZ01 | B3: 01.21010.0000.0000.0000 应付账款 | C3: EUR→CNY | D3: 2026-01-31 | E3: -469800 | F3: =SUM(J101:J101) -> 40593 | G3: =M3+SUM(G101:G101) -> -55000 | H3: =INDEX('汇率表'!$A:$XFD,MATCH(D3,'汇率表'!$A:$A,0),MATCH(L3,'汇率表'!$1:$1,0)) -> 8.3244 | I3: =G3*H3 -> -457842 | J3: =E3+F3-I3 -> 28635 | K3: CNY | L3: EUR | M3: -60000
A4: SZ01 | B4: 01.21010.0000.0000.0000 应付账款 | C4: HKD→CNY | D4: 2026-01-31 | E4: -91000 | F4: =SUM(J102:J102) -> 4488.75 | G4: =M4+SUM(G102:G102) -> -95000 | H4: =INDEX('汇率表'!$A:$XFD,MATCH(D4,'汇率表'!$A:$A,0),MATCH(L4,'汇率表'!$1:$1,0)) -> 0.89262 | I4: =G4*H4 -> -84798.9 | J4: =E4+F4-I4 -> -1712.35 | K4: CNY | L4: HKD | M4: -100000
A5: SZ01 | B5: 01.21010.0000.0000.0000 应付账款 | C5: JPY→CNY | D5: 2026-01-31 | E5: 0 | F5: =SUM(J103:J103) -> -70537.6 | G5: =M5+SUM(G103:G103) -> -1600000 | H5: =INDEX('汇率表'!$A:$XFD,MATCH(D5,'汇率表'!$A:$A,0),MATCH(L5,'汇率表'!$1:$1,0)) -> 0.045464 | I5: =G5*H5 -> -72742.4 | J5: =E5+F5-I5 -> 2204.8 | K5: CNY | L5: JPY | M5: 0
A6: SZ01 | B6: 01.21010.0000.0000.0000 应付账款 | C6: USD→CNY | D6: 2026-01-31 | E6: -284800 | F6: 0 | G6: -40000 | H6: =INDEX('汇率表'!$A:$XFD,MATCH(D6,'汇率表'!$A:$A,0),MATCH(L6,'汇率表'!$1:$1,0)) -> 6.9678 | I6: =G6*H6 -> -278712 | J6: =E6+F6-I6 -> -6088 | K6: CNY | L6: USD | M6: -40000
A7: SZ01 | B7: 01.12010.0000.0000.0000 应收账款 | C7: EUR→CNY | D7: 2026-01-31 | E7: 313200 | F7: =SUM(J104:J105) -> 31431.38 | G7: =M7+SUM(G104:G105) -> 43800 | H7: =INDEX('汇率表'!$A:$XFD,MATCH(D7,'汇率表'!$A:$A,0),MATCH(L7,'汇率表'!$1:$1,0)) -> 8.3244 | I7: =G7*H7 -> 364608.72 | J7: =E7+F7-I7 -> -19977.34 | K7: CNY | L7: EUR | M7: 40000
A8: SZ01 | B8: 01.12010.0000.0000.0000 应收账款 | C8: HKD→CNY | D8: 2026-01-31 | E8: 27300 | F8: 0 | G8: 30000 | H8: =INDEX('汇率表'!$A:$XFD,MATCH(D8,'汇率表'!$A:$A,0),MATCH(L8,'汇率表'!$1:$1,0)) -> 0.89262 | I8: =G8*H8 -> 26778.6 | J8: =E8+F8-I8 -> 521.4 | K8: CNY | L8: HKD | M8: 30000
A9: SZ01 | B9: 01.12010.0000.0000.0000 应收账款 | C9: USD→CNY | D9: 2026-01-31 | E9: 1068000 | F9: =SUM(J106:J107) -> 45758.2 | G9: =M9+SUM(G106:G107) -> 156500 | H9: =INDEX('汇率表'!$A:$XFD,MATCH(D9,'汇率表'!$A:$A,0),MATCH(L9,'汇率表'!$1:$1,0)) -> 6.9678 | I9: =G9*H9 -> 1090460.7 | J9: =E9+F9-I9 -> 23297.5 | K9: CNY | L9: USD | M9: 150000
A10: SZ01 | B10: 01.11010.0000.0000.0000 银行存款 | C10: EUR→CNY | D10: 2026-01-31 | E10: 313200 | F10: =SUM(J108:J109) -> 32367.3 | G10: =M10+SUM(G108:G109) -> 44000 | H10: =INDEX('汇率表'!$A:$XFD,MATCH(D10,'汇率表'!$A:$A,0),MATCH(L10,'汇率表'!$1:$1,0)) -> 8.3244 | I10: =G10*H10 -> 366273.6 | J10: =E10+F10-I10 -> -20706.3 | K10: CNY | L10: EUR | M10: 40000
A11: SZ01 | B11: 01.11010.0000.0000.0000 银行存款 | C11: HKD→CNY | D11: 2026-01-31 | E11: 91000 | F11: =SUM(J110:J110) -> -4488.75 | G11: =M11+SUM(G110:G110) -> 95000 | H11: =INDEX('汇率表'!$A:$XFD,MATCH(D11,'汇率表'!$A:$A,0),MATCH(L11,'汇率表'!$1:$1,0)) -> 0.89262 | I11: =G11*H11 -> 84798.9 | J11: =E11+F11-I11 -> 1712.35 | K11: CNY | L11: HKD | M11: 100000
A12: SZ01 | B12: 01.11010.0000.0000.0000 银行存款 | C12: USD→CNY | D12: 2026-01-31 | E12: 712000 | F12: =SUM(J111:J112) -> 1649213 | G12: =M12+SUM(G111:G112) -> 335000 | H12: =INDEX('汇率表'!$A:$XFD,MATCH(D12,'汇率表'!$A:$A,0),MATCH(L12,'汇率表'!$1:$1,0)) -> 6.9678 | I12: =G12*H12 -> 2334213 | J12: =E12+F12-I12 -> 27000 | K12: CNY | L12: USD | M12: 100000
A13: SZ01 | B13: 01.25010.0000.0000.0000 长期借款 | C13: USD→CNY | D13: 2026-01-31 | E13: 0 | F13: =SUM(J113:J113) -> -1403940 | G13: =M13+SUM(G113:G113) -> -200000 | H13: =INDEX('汇率表'!$A:$XFD,MATCH(D13,'汇率表'!$A:$A,0),MATCH(L13,'汇率表'!$1:$1,0)) -> 6.9678 | I13: =G13*H13 -> -1393560 | J13: =E13+F13-I13 -> -10380 | K13: CNY | L13: USD | M13: 0
A14: US01 | B14: 02.13010.0000.0000.0000 其他应收款 | C14: EUR→USD | D14: 2026-01-31 | E14: 1100 | F14: 0 | G14: 1000 | H14: =INDEX('汇率表'!$A:$XFD,MATCH(D14,'汇率表'!$A:$A,0),MATCH(L14,'汇率表'!$1:$1,0))/INDEX('汇率表'!$A:$XFD,MATCH(D14,'汇率表'!$A:$A,0),MATCH(K14,'汇率表'!$1:$1,0)) -> 1.1946956 | I14: =G14*H14 -> 1194.6956 | J14: =E14+F14-I14 -> -94.6956 | K14: USD | L14: EUR | M14: 1000
A15: US01 | B15: 02.21010.0000.0000.0000 应付账款 | C15: EUR→USD | D15: 2026-01-31 | E15: -33000 | F15: =SUM(J114:J114) -> 1391.6407 | G15: =M15+SUM(G114:G114) -> -28800 | H15: =INDEX('汇率表'!$A:$XFD,MATCH(D15,'汇率表'!$A:$A,0),MATCH(L15,'汇率表'!$1:$1,0))/INDEX('汇率表'!$A:$XFD,MATCH(D15,'汇率表'!$A:$A,0),MATCH(K15,'汇率表'!$1:$1,0)) -> 1.1946956 | I15: =G15*H15 -> -34407.233 | J15: =E15+F15-I15 -> 2798.874 | K15: USD | L15: EUR | M15: -30000
A16: US01 | B16: 02.12010.0000.0000.0000 应收账款 | C16: EUR→USD | D16: 2026-01-31 | E16: 5500 | F16: =SUM(J115:J115) -> 3721.4693 | G16: =M16+SUM(G115:G115) -> 8200 | H16: =INDEX('汇率表'!$A:$XFD,MATCH(D16,'汇率表'!$A:$A,0),MATCH(L16,'汇率表'!$1:$1,0))/INDEX('汇率表'!$A:$XFD,MATCH(D16,'汇率表'!$A:$A,0),MATCH(K16,'汇率表'!$1:$1,0)) -> 1.1946956 | I16: =G16*H16 -> 9796.5039 | J16: =E16+F16-I16 -> -575.0346 | K16: USD | L16: EUR | M16: 5000
A17: US01 | B17: 02.11010.0000.0000.0000 银行存款 | C17: EUR→USD | D17: 2026-01-31 | E17: 22000 | F17: =SUM(J116:J116) -> -1391.6407 | G17: =M17+SUM(G116:G116) -> 18800 | H17: =INDEX('汇率表'!$A:$XFD,MATCH(D17,'汇率表'!$A:$A,0),MATCH(L17,'汇率表'!$1:$1,0))/INDEX('汇率表'!$A:$XFD,MATCH(D17,'汇率表'!$A:$A,0),MATCH(K17,'汇率表'!$1:$1,0)) -> 1.1946956 | I17: =G17*H17 -> 22460.277 | J17: =E17+F17-I17 -> -1851.918 | K17: USD | L17: EUR | M17: 20000
A18: SZ01 | B18: 01.13010.0000.0000.0000 其他应收款 | C18: USD→CNY | D18: 2026-02-28 | E18: =I2 -> 34839 | F18: 0 | G18: 5000 | H18: =INDEX('汇率表'!$A:$XFD,MATCH(D18,'汇率表'!$A:$A,0),MATCH(L18,'汇率表'!$1:$1,0)) -> 6.9228 | I18: =G18*H18 -> 34614 | J18: =E18+F18-I18 -> 225 | K18: CNY | L18: USD | M18: 5000
A19: SZ01 | B19: 01.21010.0000.0000.0000 应付账款 | C19: EUR→CNY | D19: 2026-02-28 | E19: =I3 -> -457842 | F19: =SUM(J117:J118) -> -370167.5 | G19: =M19+SUM(G117:G118) -> -100000 | H19: =INDEX('汇率表'!$A:$XFD,MATCH(D19,'汇率表'!$A:$A,0),MATCH(L19,'汇率表'!$1:$1,0)) -> 8.1208 | I19: =G19*H19 -> -812080 | J19: =E19+F19-I19 -> -15929.5 | K19: CNY | L19: EUR | M19: -55000
A20: SZ01 | B20: 01.21010.0000.0000.0000 应付账款 | C20: HKD→CNY | D20: 2026-02-28 | E20: =I4 -> -84798.9 | F20: =SUM(J119:J119) -> 4439.35 | G20: =M20+SUM(G119:G119) -> -90000 | H20: =INDEX('汇率表'!$A:$XFD,MATCH(D20,'汇率表'!$A:$A,0),MATCH(L20,'汇率表'!$1:$1,0)) -> 0.88484 | I20: =G20*H20 -> -79635.6 | J20: =E20+F20-I20 -> -723.95 | K20: CNY | L20: HKD | M20: -95000
A21: SZ01 | B21: 01.21010.0000.0000.0000 应付账款 | C21: JPY→CNY | D21: 2026-02-28 | E21: =I5 -> -72742.4 | F21: =SUM(J120:J120) -> -77016.8 | G21: =M21+SUM(G120:G120) -> -3300000 | H21: =INDEX('汇率表'!$A:$XFD,MATCH(D21,'汇率表'!$A:$A,0),MATCH(L21,'汇率表'!$1:$1,0)) -> 0.044216 | I21: =G21*H21 -> -145912.8 | J21: =E21+F21-I21 -> -3846.4 | K21: CNY | L21: JPY | M21: -1600000
A22: SZ01 | B22: 01.21010.0000.0000.0000 应付账款 | C22: USD→CNY | D22: 2026-02-28 | E22: =I6 -> -278712 | F22: 0 | G22: -40000 | H22: =INDEX('汇率表'!$A:$XFD,MATCH(D22,'汇率表'!$A:$A,0),MATCH(L22,'汇率表'!$1:$1,0)) -> 6.9228 | I22: =G22*H22 -> -276912 | J22: =E22+F22-I22 -> -1800 | K22: CNY | L22: USD | M22: -40000
A23: SZ01 | B23: 01.12010.0000.0000.0000 应收账款 | C23: EUR→CNY | D23: 2026-02-28 | E23: =I7 -> 364608.72 | F23: =SUM(J121:J122) -> 38242.18 | G23: =M23+SUM(G121:G122) -> 48400 | H23: =INDEX('汇率表'!$A:$XFD,MATCH(D23,'汇率表'!$A:$A,0),MATCH(L23,'汇率表'!$1:$1,0)) -> 8.1208 | I23: =G23*H23 -> 393046.72 | J23: =E23+F23-I23 -> 9804.18 | K23: CNY | L23: EUR | M23: 43800
A24: SZ01 | B24: 01.12010.0000.0000.0000 应收账款 | C24: HKD→CNY | D24: 2026-02-28 | E24: =I8 -> 26778.6 | F24: 0 | G24: 30000 | H24: =INDEX('汇率表'!$A:$XFD,MATCH(D24,'汇率表'!$A:$A,0),MATCH(L24,'汇率表'!$1:$1,0)) -> 0.88484 | I24: =G24*H24 -> 26545.2 | J24: =E24+F24-I24 -> 233.4 | K24: CNY | L24: HKD | M24: 30000
A25: SZ01 | B25: 01.12010.0000.0000.0000 应收账款 | C25: USD→CNY | D25: 2026-02-28 | E25: =I9 -> 1090460.7 | F25: =SUM(J123:J124) -> 55776.4 | G25: =M25+SUM(G123:G124) -> 164500 | H25: =INDEX('汇率表'!$A:$XFD,MATCH(D25,'汇率表'!$A:$A,0),MATCH(L25,'汇率表'!$1:$1,0)) -> 6.9228 | I25: =G25*H25 -> 1138800.6 | J25: =E25+F25-I25 -> 7436.5 | K25: CNY | L25: USD | M25: 156500
A26: SZ01 | B26: 01.11010.0000.0000.0000 银行存款 | C26: EUR→CNY | D26: 2026-02-28 | E26: =I10 -> 366273.6 | F26: =SUM(J125:J126) -> 32878 | G26: =M26+SUM(G125:G126) -> 48000 | H26: =INDEX('汇率表'!$A:$XFD,MATCH(D26,'汇率表'!$A:$A,0),MATCH(L26,'汇率表'!$1:$1,0)) -> 8.1208 | I26: =G26*H26 -> 389798.4 | J26: =E26+F26-I26 -> 9353.2 | K26: CNY | L26: EUR | M26: 44000
A27: SZ01 | B27: 01.11010.0000.0000.0000 银行存款 | C27: HKD→CNY | D27: 2026-02-28 | E27: =I11 -> 84798.9 | F27: =SUM(J127:J127) -> -4439.35 | G27: =M27+SUM(G127:G127) -> 90000 | H27: =INDEX('汇率表'!$A:$XFD,MATCH(D27,'汇率表'!$A:$A,0),MATCH(L27,'汇率表'!$1:$1,0)) -> 0.88484 | I27: =G27*H27 -> 79635.6 | J27: =E27+F27-I27 -> 723.95 | K27: CNY | L27: HKD | M27: 95000
A28: SZ01 | B28: 01.11010.0000.0000.0000 银行存款 | C28: USD→CNY | D28: 2026-02-28 | E28: =I12 -> 2334213 | F28: =SUM(J128:J128) -> 242893 | G28: =M28+SUM(G128:G128) -> 370000 | H28: =INDEX('汇率表'!$A:$XFD,MATCH(D28,'汇率表'!$A:$A,0),MATCH(L28,'汇率表'!$1:$1,0)) -> 6.9228 | I28: =G28*H28 -> 2561436 | J28: =E28+F28-I28 -> 15670 | K28: CNY | L28: USD | M28: 335000
A29: SZ01 | B29: 01.25010.0000.0000.0000 长期借款 | C29: USD→CNY | D29: 2026-02-28 | E29: =I13 -> -1393560 | F29: 0 | G29: -200000 | H29: =INDEX('汇率表'!$A:$XFD,MATCH(D29,'汇率表'!$A:$A,0),MATCH(L29,'汇率表'!$1:$1,0)) -> 6.9228 | I29: =G29*H29 -> -1384560 | J29: =E29+F29-I29 -> -9000 | K29: CNY | L29: USD | M29: -200000
A30: US01 | B30: 02.13010.0000.0000.0000 其他应收款 | C30: EUR→USD | D30: 2026-02-28 | E30: =I14 -> 1194.6956 | F30: 0 | G30: 1000 | H30: =INDEX('汇率表'!$A:$XFD,MATCH(D30,'汇率表'!$A:$A,0),MATCH(L30,'汇率表'!$1:$1,0))/INDEX('汇率表'!$A:$XFD,MATCH(D30,'汇率表'!$A:$A,0),MATCH(K30,'汇率表'!$1:$1,0)) -> 1.1730514 | I30: =G30*H30 -> 1173.0514 | J30: =E30+F30-I30 -> 21.644233 | K30: USD | L30: EUR | M30: 1000
A31: US01 | B31: 02.21010.0000.0000.0000 应付账款 | C31: EUR→USD | D31: 2026-02-28 | E31: =I15 -> -34407.233 | F31: =SUM(J129:J129) -> 1421.2802 | G31: =M31+SUM(G129:G129) -> -27600 | H31: =INDEX('汇率表'!$A:$XFD,MATCH(D31,'汇率表'!$A:$A,0),MATCH(L31,'汇率表'!$1:$1,0))/INDEX('汇率表'!$A:$XFD,MATCH(D31,'汇率表'!$A:$A,0),MATCH(K31,'汇率表'!$1:$1,0)) -> 1.1730514 | I31: =G31*H31 -> -32376.218 | J31: =E31+F31-I31 -> -609.73541 | K31: USD | L31: EUR | M31: -28800
A32: US01 | B32: 02.12010.0000.0000.0000 应收账款 | C32: EUR→USD | D32: 2026-02-28 | E32: =I16 -> 9796.5039 | F32: =SUM(J130:J130) -> 4039.0481 | G32: =M32+SUM(G130:G130) -> 11600 | H32: =INDEX('汇率表'!$A:$XFD,MATCH(D32,'汇率表'!$A:$A,0),MATCH(L32,'汇率表'!$1:$1,0))/INDEX('汇率表'!$A:$XFD,MATCH(D32,'汇率表'!$A:$A,0),MATCH(K32,'汇率表'!$1:$1,0)) -> 1.1730514 | I32: =G32*H32 -> 13607.396 | J32: =E32+F32-I32 -> 228.15612 | K32: USD | L32: EUR | M32: 8200
A33: US01 | B33: 02.11010.0000.0000.0000 银行存款 | C33: EUR→USD | D33: 2026-02-28 | E33: =I17 -> 22460.277 | F33: =SUM(J131:J131) -> -1421.2802 | G33: =M33+SUM(G131:G131) -> 17600 | H33: =INDEX('汇率表'!$A:$XFD,MATCH(D33,'汇率表'!$A:$A,0),MATCH(L33,'汇率表'!$1:$1,0))/INDEX('汇率表'!$A:$XFD,MATCH(D33,'汇率表'!$A:$A,0),MATCH(K33,'汇率表'!$1:$1,0)) -> 1.1730514 | I33: =G33*H33 -> 20645.704 | J33: =E33+F33-I33 -> 393.29307 | K33: USD | L33: EUR | M33: 18800
A34: SZ01 | B34: 01.13010.0000.0000.0000 其他应收款 | C34: USD→CNY | D34: 2026-03-31 | E34: =I18 -> 34614 | F34: 0 | G34: 5000 | H34: =INDEX('汇率表'!$A:$XFD,MATCH(D34,'汇率表'!$A:$A,0),MATCH(L34,'汇率表'!$1:$1,0)) -> 6.9194 | I34: =G34*H34 -> 34597 | J34: =E34+F34-I34 -> 17 | K34: CNY | L34: USD | M34: 5000
A35: SZ01 | B35: 01.21010.0000.0000.0000 应付账款 | C35: EUR→CNY | D35: 2026-03-31 | E35: =I19 -> -812080 | F35: =SUM(J132:J132) -> 39837.5 | G35: =M35+SUM(G132:G132) -> -95000 | H35: =INDEX('汇率表'!$A:$XFD,MATCH(D35,'汇率表'!$A:$A,0),MATCH(L35,'汇率表'!$1:$1,0)) -> 7.9302 | I35: =G35*H35 -> -753369 | J35: =E35+F35-I35 -> -18873.5 | K35: CNY | L35: EUR | M35: -100000
A36: SZ01 | B36: 01.21010.0000.0000.0000 应付账款 | C36: HKD→CNY | D36: 2026-03-31 | E36: =I20 -> -79635.6 | F36: =SUM(J133:J133) -> 4395.75 | G36: =M36+SUM(G133:G133) -> -85000 | H36: =INDEX('汇率表'!$A:$XFD,MATCH(D36,'汇率表'!$A:$A,0),MATCH(L36,'汇率表'!$1:$1,0)) -> 0.88295 | I36: =G36*H36 -> -75050.75 | J36: =E36+F36-I36 -> -189.1 | K36: CNY | L36: HKD | M36: -90000
A37: SZ01 | B37: 01.21010.0000.0000.0000 应付账款 | C37: JPY→CNY | D37: 2026-03-31 | E37: =I21 -> -145912.8 | F37: =SUM(J134:J134) -> -77911.2 | G37: =M37+SUM(G134:G134) -> -5100000 | H37: =INDEX('汇率表'!$A:$XFD,MATCH(D37,'汇率表'!$A:$A,0),MATCH(L37,'汇率表'!$1:$1,0)) -> 0.043296 | I37: =G37*H37 -> -220809.6 | J37: =E37+F37-I37 -> -3014.4 | K37: CNY | L37: JPY | M37: -3300000
A38: SZ01 | B38: 01.21010.0000.0000.0000 应付账款 | C38: USD→CNY | D38: 2026-03-31 | E38: =I22 -> -276912 | F38: 0 | G38: -40000 | H38: =INDEX('汇率表'!$A:$XFD,MATCH(D38,'汇率表'!$A:$A,0),MATCH(L38,'汇率表'!$1:$1,0)) -> 6.9194 | I38: =G38*H38 -> -276776 | J38: =E38+F38-I38 -> -136 | K38: CNY | L38: USD | M38: -40000
A39: SZ01 | B39: 01.12010.0000.0000.0000 应收账款 | C39: EUR→CNY | D39: 2026-03-31 | E39: =I23 -> 393046.72 | F39: =SUM(J135:J136) -> 44002.62 | G39: =M39+SUM(G135:G136) -> 53800 | H39: =INDEX('汇率表'!$A:$XFD,MATCH(D39,'汇率表'!$A:$A,0),MATCH(L39,'汇率表'!$1:$1,0)) -> 7.9302 | I39: =G39*H39 -> 426644.76 | J39: =E39+F39-I39 -> 10404.58 | K39: CNY | L39: EUR | M39: 48400
A40: SZ01 | B40: 01.12010.0000.0000.0000 应收账款 | C40: HKD→CNY | D40: 2026-03-31 | E40: =I24 -> 26545.2 | F40: 0 | G40: 30000 | H40: =INDEX('汇率表'!$A:$XFD,MATCH(D40,'汇率表'!$A:$A,0),MATCH(L40,'汇率表'!$1:$1,0)) -> 0.88295 | I40: =G40*H40 -> 26488.5 | J40: =E40+F40-I40 -> 56.7 | K40: CNY | L40: HKD | M40: 30000
...

Sheet 客户与审计汇率比较
A1: 类型 | B1: 日期 | C1: 凭证号 | D1: 主体 | E1: 科目 | F1: 币种（原币→本位币） | G1: 原币基础 | H1: 客户本位币金额 | I1: 客户隐含汇率 | J1: 审计适用汇率 | K1: 汇率差（客户－审计） | L1: 反推依据 | M1: 本位币（公式辅助） | N1: 原币（公式辅助）
A2: 未实现 | B2: 2026-01-31 | D2: SZ01 | E2: 01.13010.0000.0000.0000 其他应收款 | F2: USD→CNY | G2: 5000 | H2: 35600 | I2: =H2/G2 -> 7.12 | J2: =INDEX('汇率表'!$A:$XFD,MATCH(B2,'汇率表'!$A:$A,0),MATCH(N2,'汇率表'!$1:$1,0)) -> 6.9678 | K2: =I2-J2 -> 0.1522 | L2: TB期初本位币及JE滚动后账面余额÷月末原币余额反推 | M2: CNY | N2: USD
A3: 未实现 | B3: 2026-01-31 | D3: SZ01 | E3: 01.21010.0000.0000.0000 应付账款 | F3: EUR→CNY | G3: -55000 | H3: -430650 | I3: =H3/G3 -> 7.83 | J3: =INDEX('汇率表'!$A:$XFD,MATCH(B3,'汇率表'!$A:$A,0),MATCH(N3,'汇率表'!$1:$1,0)) -> 8.3244 | K3: =I3-J3 -> -0.4944 | L3: TB期初本位币及JE滚动后账面余额÷月末原币余额反推 | M3: CNY | N3: EUR
A4: 未实现 | B4: 2026-01-31 | D4: SZ01 | E4: 01.21010.0000.0000.0000 应付账款 | F4: HKD→CNY | G4: -95000 | H4: -86450 | I4: =H4/G4 -> 0.91 | J4: =INDEX('汇率表'!$A:$XFD,MATCH(B4,'汇率表'!$A:$A,0),MATCH(N4,'汇率表'!$1:$1,0)) -> 0.89262 | K4: =I4-J4 -> 0.01738 | L4: TB期初本位币及JE滚动后账面余额÷月末原币余额反推 | M4: CNY | N4: HKD
A5: 未实现 | B5: 2026-01-31 | D5: SZ01 | E5: 01.21010.0000.0000.0000 应付账款 | F5: JPY→CNY | G5: -1600000 | H5: -77120 | I5: =H5/G5 -> 0.0482 | J5: =INDEX('汇率表'!$A:$XFD,MATCH(B5,'汇率表'!$A:$A,0),MATCH(N5,'汇率表'!$1:$1,0)) -> 0.045464 | K5: =I5-J5 -> 0.002736 | L5: TB期初本位币及JE滚动后账面余额÷月末原币余额反推 | M5: CNY | N5: JPY
A6: 未实现 | B6: 2026-01-31 | D6: SZ01 | E6: 01.21010.0000.0000.0000 应付账款 | F6: USD→CNY | G6: -40000 | H6: -284800 | I6: =H6/G6 -> 7.12 | J6: =INDEX('汇率表'!$A:$XFD,MATCH(B6,'汇率表'!$A:$A,0),MATCH(N6,'汇率表'!$1:$1,0)) -> 6.9678 | K6: =I6-J6 -> 0.1522 | L6: TB期初本位币及JE滚动后账面余额÷月末原币余额反推 | M6: CNY | N6: USD
A7: 未实现 | B7: 2026-01-31 | D7: SZ01 | E7: 01.12010.0000.0000.0000 应收账款 | F7: EUR→CNY | G7: 43800 | H7: 342954 | I7: =H7/G7 -> 7.83 | J7: =INDEX('汇率表'!$A:$XFD,MATCH(B7,'汇率表'!$A:$A,0),MATCH(N7,'汇率表'!$1:$1,0)) -> 8.3244 | K7: =I7-J7 -> -0.4944 | L7: TB期初本位币及JE滚动后账面余额÷月末原币余额反推 | M7: CNY | N7: EUR
A8: 未实现 | B8: 2026-01-31 | D8: SZ01 | E8: 01.12010.0000.0000.0000 应收账款 | F8: HKD→CNY | G8: 30000 | H8: 27300 | I8: =H8/G8 -> 0.91 | J8: =INDEX('汇率表'!$A:$XFD,MATCH(B8,'汇率表'!$A:$A,0),MATCH(N8,'汇率表'!$1:$1,0)) -> 0.89262 | K8: =I8-J8 -> 0.01738 | L8: TB期初本位币及JE滚动后账面余额÷月末原币余额反推 | M8: CNY | N8: HKD
A9: 未实现 | B9: 2026-01-31 | D9: SZ01 | E9: 01.12010.0000.0000.0000 应收账款 | F9: USD→CNY | G9: 156500 | H9: 1114280 | I9: =H9/G9 -> 7.12 | J9: =INDEX('汇率表'!$A:$XFD,MATCH(B9,'汇率表'!$A:$A,0),MATCH(N9,'汇率表'!$1:$1,0)) -> 6.9678 | K9: =I9-J9 -> 0.1522 | L9: TB期初本位币及JE滚动后账面余额÷月末原币余额反推 | M9: CNY | N9: USD
A10: 未实现 | B10: 2026-01-31 | D10: SZ01 | E10: 01.11010.0000.0000.0000 银行存款 | F10: EUR→CNY | G10: 44000 | H10: 344520 | I10: =H10/G10 -> 7.83 | J10: =INDEX('汇率表'!$A:$XFD,MATCH(B10,'汇率表'!$A:$A,0),MATCH(N10,'汇率表'!$1:$1,0)) -> 8.3244 | K10: =I10-J10 -> -0.4944 | L10: TB期初本位币及JE滚动后账面余额÷月末原币余额反推 | M10: CNY | N10: EUR
A11: 未实现 | B11: 2026-01-31 | D11: SZ01 | E11: 01.11010.0000.0000.0000 银行存款 | F11: HKD→CNY | G11: 95000 | H11: 86450 | I11: =H11/G11 -> 0.91 | J11: =INDEX('汇率表'!$A:$XFD,MATCH(B11,'汇率表'!$A:$A,0),MATCH(N11,'汇率表'!$1:$1,0)) -> 0.89262 | K11: =I11-J11 -> 0.01738 | L11: TB期初本位币及JE滚动后账面余额÷月末原币余额反推 | M11: CNY | N11: HKD
A12: 未实现 | B12: 2026-01-31 | D12: SZ01 | E12: 01.11010.0000.0000.0000 银行存款 | F12: USD→CNY | G12: 335000 | H12: 2385200 | I12: =H12/G12 -> 7.12 | J12: =INDEX('汇率表'!$A:$XFD,MATCH(B12,'汇率表'!$A:$A,0),MATCH(N12,'汇率表'!$1:$1,0)) -> 6.9678 | K12: =I12-J12 -> 0.1522 | L12: TB期初本位币及JE滚动后账面余额÷月末原币余额反推 | M12: CNY | N12: USD
A13: 未实现 | B13: 2026-01-31 | D13: SZ01 | E13: 01.25010.0000.0000.0000 长期借款 | F13: USD→CNY | G13: -200000 | H13: -1424000 | I13: =H13/G13 -> 7.12 | J13: =INDEX('汇率表'!$A:$XFD,MATCH(B13,'汇率表'!$A:$A,0),MATCH(N13,'汇率表'!$1:$1,0)) -> 6.9678 | K13: =I13-J13 -> 0.1522 | L13: TB期初本位币及JE滚动后账面余额÷月末原币余额反推 | M13: CNY | N13: USD
A14: 未实现 | B14: 2026-01-31 | D14: US01 | E14: 02.13010.0000.0000.0000 其他应收款 | F14: EUR→USD | G14: 1000 | H14: 1100 | I14: =H14/G14 -> 1.1 | J14: =INDEX('汇率表'!$A:$XFD,MATCH(B14,'汇率表'!$A:$A,0),MATCH(N14,'汇率表'!$1:$1,0))/INDEX('汇率表'!$A:$XFD,MATCH(B14,'汇率表'!$A:$A,0),MATCH(M14,'汇率表'!$1:$1,0)) -> 1.1946956 | K14: =I14-J14 -> -0.0946956 | L14: TB期初本位币及JE滚动后账面余额÷月末原币余额反推 | M14: USD | N14: EUR
A15: 未实现 | B15: 2026-01-31 | D15: US01 | E15: 02.21010.0000.0000.0000 应付账款 | F15: EUR→USD | G15: -28800 | H15: -31680 | I15: =H15/G15 -> 1.1 | J15: =INDEX('汇率表'!$A:$XFD,MATCH(B15,'汇率表'!$A:$A,0),MATCH(N15,'汇率表'!$1:$1,0))/INDEX('汇率表'!$A:$XFD,MATCH(B15,'汇率表'!$A:$A,0),MATCH(M15,'汇率表'!$1:$1,0)) -> 1.1946956 | K15: =I15-J15 -> -0.0946956 | L15: TB期初本位币及JE滚动后账面余额÷月末原币余额反推 | M15: USD | N15: EUR
A16: 未实现 | B16: 2026-01-31 | D16: US01 | E16: 02.12010.0000.0000.0000 应收账款 | F16: EUR→USD | G16: 8200 | H16: 9020 | I16: =H16/G16 -> 1.1 | J16: =INDEX('汇率表'!$A:$XFD,MATCH(B16,'汇率表'!$A:$A,0),MATCH(N16,'汇率表'!$1:$1,0))/INDEX('汇率表'!$A:$XFD,MATCH(B16,'汇率表'!$A:$A,0),MATCH(M16,'汇率表'!$1:$1,0)) -> 1.1946956 | K16: =I16-J16 -> -0.0946956 | L16: TB期初本位币及JE滚动后账面余额÷月末原币余额反推 | M16: USD | N16: EUR
A17: 未实现 | B17: 2026-01-31 | D17: US01 | E17: 02.11010.0000.0000.0000 银行存款 | F17: EUR→USD | G17: 18800 | H17: 20680 | I17: =H17/G17 -> 1.1 | J17: =INDEX('汇率表'!$A:$XFD,MATCH(B17,'汇率表'!$A:$A,0),MATCH(N17,'汇率表'!$1:$1,0))/INDEX('汇率表'!$A:$XFD,MATCH(B17,'汇率表'!$A:$A,0),MATCH(M17,'汇率表'!$1:$1,0)) -> 1.1946956 | K17: =I17-J17 -> -0.0946956 | L17: TB期初本位币及JE滚动后账面余额÷月末原币余额反推 | M17: USD | N17: EUR
A18: 未实现 | B18: 2026-02-28 | D18: SZ01 | E18: 01.13010.0000.0000.0000 其他应收款 | F18: USD→CNY | G18: 5000 | H18: 35600 | I18: =H18/G18 -> 7.12 | J18: =INDEX('汇率表'!$A:$XFD,MATCH(B18,'汇率表'!$A:$A,0),MATCH(N18,'汇率表'!$1:$1,0)) -> 6.9228 | K18: =I18-J18 -> 0.1972 | L18: TB期初本位币及JE滚动后账面余额÷月末原币余额反推 | M18: CNY | N18: USD
A19: 未实现 | B19: 2026-02-28 | D19: SZ01 | E19: 01.21010.0000.0000.0000 应付账款 | F19: EUR→CNY | G19: -100000 | H19: -783000 | I19: =H19/G19 -> 7.83 | J19: =INDEX('汇率表'!$A:$XFD,MATCH(B19,'汇率表'!$A:$A,0),MATCH(N19,'汇率表'!$1:$1,0)) -> 8.1208 | K19: =I19-J19 -> -0.2908 | L19: TB期初本位币及JE滚动后账面余额÷月末原币余额反推 | M19: CNY | N19: EUR
A20: 未实现 | B20: 2026-02-28 | D20: SZ01 | E20: 01.21010.0000.0000.0000 应付账款 | F20: HKD→CNY | G20: -90000 | H20: -81900 | I20: =H20/G20 -> 0.91 | J20: =INDEX('汇率表'!$A:$XFD,MATCH(B20,'汇率表'!$A:$A,0),MATCH(N20,'汇率表'!$1:$1,0)) -> 0.88484 | K20: =I20-J20 -> 0.02516 | L20: TB期初本位币及JE滚动后账面余额÷月末原币余额反推 | M20: CNY | N20: HKD
A21: 未实现 | B21: 2026-02-28 | D21: SZ01 | E21: 01.21010.0000.0000.0000 应付账款 | F21: JPY→CNY | G21: -3300000 | H21: -159060 | I21: =H21/G21 -> 0.0482 | J21: =INDEX('汇率表'!$A:$XFD,MATCH(B21,'汇率表'!$A:$A,0),MATCH(N21,'汇率表'!$1:$1,0)) -> 0.044216 | K21: =I21-J21 -> 0.003984 | L21: TB期初本位币及JE滚动后账面余额÷月末原币余额反推 | M21: CNY | N21: JPY
A22: 未实现 | B22: 2026-02-28 | D22: SZ01 | E22: 01.21010.0000.0000.0000 应付账款 | F22: USD→CNY | G22: -40000 | H22: -284800 | I22: =H22/G22 -> 7.12 | J22: =INDEX('汇率表'!$A:$XFD,MATCH(B22,'汇率表'!$A:$A,0),MATCH(N22,'汇率表'!$1:$1,0)) -> 6.9228 | K22: =I22-J22 -> 0.1972 | L22: TB期初本位币及JE滚动后账面余额÷月末原币余额反推 | M22: CNY | N22: USD
A23: 未实现 | B23: 2026-02-28 | D23: SZ01 | E23: 01.12010.0000.0000.0000 应收账款 | F23: EUR→CNY | G23: 48400 | H23: 378972 | I23: =H23/G23 -> 7.83 | J23: =INDEX('汇率表'!$A:$XFD,MATCH(B23,'汇率表'!$A:$A,0),MATCH(N23,'汇率表'!$1:$1,0)) -> 8.1208 | K23: =I23-J23 -> -0.2908 | L23: TB期初本位币及JE滚动后账面余额÷月末原币余额反推 | M23: CNY | N23: EUR
A24: 未实现 | B24: 2026-02-28 | D24: SZ01 | E24: 01.12010.0000.0000.0000 应收账款 | F24: HKD→CNY | G24: 30000 | H24: 27300 | I24: =H24/G24 -> 0.91 | J24: =INDEX('汇率表'!$A:$XFD,MATCH(B24,'汇率表'!$A:$A,0),MATCH(N24,'汇率表'!$1:$1,0)) -> 0.88484 | K24: =I24-J24 -> 0.02516 | L24: TB期初本位币及JE滚动后账面余额÷月末原币余额反推 | M24: CNY | N24: HKD
A25: 未实现 | B25: 2026-02-28 | D25: SZ01 | E25: 01.12010.0000.0000.0000 应收账款 | F25: USD→CNY | G25: 164500 | H25: 1171240 | I25: =H25/G25 -> 7.12 | J25: =INDEX('汇率表'!$A:$XFD,MATCH(B25,'汇率表'!$A:$A,0),MATCH(N25,'汇率表'!$1:$1,0)) -> 6.9228 | K25: =I25-J25 -> 0.1972 | L25: TB期初本位币及JE滚动后账面余额÷月末原币余额反推 | M25: CNY | N25: USD
A26: 未实现 | B26: 2026-02-28 | D26: SZ01 | E26: 01.11010.0000.0000.0000 银行存款 | F26: EUR→CNY | G26: 48000 | H26: 375840 | I26: =H26/G26 -> 7.83 | J26: =INDEX('汇率表'!$A:$XFD,MATCH(B26,'汇率表'!$A:$A,0),MATCH(N26,'汇率表'!$1:$1,0)) -> 8.1208 | K26: =I26-J26 -> -0.2908 | L26: TB期初本位币及JE滚动后账面余额÷月末原币余额反推 | M26: CNY | N26: EUR
A27: 未实现 | B27: 2026-02-28 | D27: SZ01 | E27: 01.11010.0000.0000.0000 银行存款 | F27: HKD→CNY | G27: 90000 | H27: 81900 | I27: =H27/G27 -> 0.91 | J27: =INDEX('汇率表'!$A:$XFD,MATCH(B27,'汇率表'!$A:$A,0),MATCH(N27,'汇率表'!$1:$1,0)) -> 0.88484 | K27: =I27-J27 -> 0.02516 | L27: TB期初本位币及JE滚动后账面余额÷月末原币余额反推 | M27: CNY | N27: HKD
A28: 未实现 | B28: 2026-02-28 | D28: SZ01 | E28: 01.11010.0000.0000.0000 银行存款 | F28: USD→CNY | G28: 370000 | H28: 2634400 | I28: =H28/G28 -> 7.12 | J28: =INDEX('汇率表'!$A:$XFD,MATCH(B28,'汇率表'!$A:$A,0),MATCH(N28,'汇率表'!$1:$1,0)) -> 6.9228 | K28: =I28-J28 -> 0.1972 | L28: TB期初本位币及JE滚动后账面余额÷月末原币余额反推 | M28: CNY | N28: USD
A29: 未实现 | B29: 2026-02-28 | D29: SZ01 | E29: 01.25010.0000.0000.0000 长期借款 | F29: USD→CNY | G29: -200000 | H29: -1424000 | I29: =H29/G29 -> 7.12 | J29: =INDEX('汇率表'!$A:$XFD,MATCH(B29,'汇率表'!$A:$A,0),MATCH(N29,'汇率表'!$1:$1,0)) -> 6.9228 | K29: =I29-J29 -> 0.1972 | L29: TB期初本位币及JE滚动后账面余额÷月末原币余额反推 | M29: CNY | N29: USD
A30: 未实现 | B30: 2026-02-28 | D30: US01 | E30: 02.13010.0000.0000.0000 其他应收款 | F30: EUR→USD | G30: 1000 | H30: 1100 | I30: =H30/G30 -> 1.1 | J30: =INDEX('汇率表'!$A:$XFD,MATCH(B30,'汇率表'!$A:$A,0),MATCH(N30,'汇率表'!$1:$1,0))/INDEX('汇率表'!$A:$XFD,MATCH(B30,'汇率表'!$A:$A,0),MATCH(M30,'汇率表'!$1:$1,0)) -> 1.1730514 | K30: =I30-J30 -> -0.073051366 | L30: TB期初本位币及JE滚动后账面余额÷月末原币余额反推 | M30: USD | N30: EUR
A31: 未实现 | B31: 2026-02-28 | D31: US01 | E31: 02.21010.0000.0000.0000 应付账款 | F31: EUR→USD | G31: -27600 | H31: -30360 | I31: =H31/G31 -> 1.1 | J31: =INDEX('汇率表'!$A:$XFD,MATCH(B31,'汇率表'!$A:$A,0),MATCH(N31,'汇率表'!$1:$1,0))/INDEX('汇率表'!$A:$XFD,MATCH(B31,'汇率表'!$A:$A,0),MATCH(M31,'汇率表'!$1:$1,0)) -> 1.1730514 | K31: =I31-J31 -> -0.073051366 | L31: TB期初本位币及JE滚动后账面余额÷月末原币余额反推 | M31: USD | N31: EUR
A32: 未实现 | B32: 2026-02-28 | D32: US01 | E32: 02.12010.0000.0000.0000 应收账款 | F32: EUR→USD | G32: 11600 | H32: 12760 | I32: =H32/G32 -> 1.1 | J32: =INDEX('汇率表'!$A:$XFD,MATCH(B32,'汇率表'!$A:$A,0),MATCH(N32,'汇率表'!$1:$1,0))/INDEX('汇率表'!$A:$XFD,MATCH(B32,'汇率表'!$A:$A,0),MATCH(M32,'汇率表'!$1:$1,0)) -> 1.1730514 | K32: =I32-J32 -> -0.073051366 | L32: TB期初本位币及JE滚动后账面余额÷月末原币余额反推 | M32: USD | N32: EUR
A33: 未实现 | B33: 2026-02-28 | D33: US01 | E33: 02.11010.0000.0000.0000 银行存款 | F33: EUR→USD | G33: 17600 | H33: 19360 | I33: =H33/G33 -> 1.1 | J33: =INDEX('汇率表'!$A:$XFD,MATCH(B33,'汇率表'!$A:$A,0),MATCH(N33,'汇率表'!$1:$1,0))/INDEX('汇率表'!$A:$XFD,MATCH(B33,'汇率表'!$A:$A,0),MATCH(M33,'汇率表'!$1:$1,0)) -> 1.1730514 | K33: =I33-J33 -> -0.073051366 | L33: TB期初本位币及JE滚动后账面余额÷月末原币余额反推 | M33: USD | N33: EUR
A34: 未实现 | B34: 2026-03-31 | D34: SZ01 | E34: 01.13010.0000.0000.0000 其他应收款 | F34: USD→CNY | G34: 5000 | H34: 35600 | I34: =H34/G34 -> 7.12 | J34: =INDEX('汇率表'!$A:$XFD,MATCH(B34,'汇率表'!$A:$A,0),MATCH(N34,'汇率表'!$1:$1,0)) -> 6.9194 | K34: =I34-J34 -> 0.2006 | L34: TB期初本位币及JE滚动后账面余额÷月末原币余额反推 | M34: CNY | N34: USD
A35: 未实现 | B35: 2026-03-31 | D35: SZ01 | E35: 01.21010.0000.0000.0000 应付账款 | F35: EUR→CNY | G35: -95000 | H35: -743850 | I35: =H35/G35 -> 7.83 | J35: =INDEX('汇率表'!$A:$XFD,MATCH(B35,'汇率表'!$A:$A,0),MATCH(N35,'汇率表'!$1:$1,0)) -> 7.9302 | K35: =I35-J35 -> -0.1002 | L35: TB期初本位币及JE滚动后账面余额÷月末原币余额反推 | M35: CNY | N35: EUR
A36: 未实现 | B36: 2026-03-31 | D36: SZ01 | E36: 01.21010.0000.0000.0000 应付账款 | F36: HKD→CNY | G36: -85000 | H36: -77350 | I36: =H36/G36 -> 0.91 | J36: =INDEX('汇率表'!$A:$XFD,MATCH(B36,'汇率表'!$A:$A,0),MATCH(N36,'汇率表'!$1:$1,0)) -> 0.88295 | K36: =I36-J36 -> 0.02705 | L36: TB期初本位币及JE滚动后账面余额÷月末原币余额反推 | M36: CNY | N36: HKD
A37: 未实现 | B37: 2026-03-31 | D37: SZ01 | E37: 01.21010.0000.0000.0000 应付账款 | F37: JPY→CNY | G37: -5100000 | H37: -245820 | I37: =H37/G37 -> 0.0482 | J37: =INDEX('汇率表'!$A:$XFD,MATCH(B37,'汇率表'!$A:$A,0),MATCH(N37,'汇率表'!$1:$1,0)) -> 0.043296 | K37: =I37-J37 -> 0.004904 | L37: TB期初本位币及JE滚动后账面余额÷月末原币余额反推 | M37: CNY | N37: JPY
A38: 未实现 | B38: 2026-03-31 | D38: SZ01 | E38: 01.21010.0000.0000.0000 应付账款 | F38: USD→CNY | G38: -40000 | H38: -284800 | I38: =H38/G38 -> 7.12 | J38: =INDEX('汇率表'!$A:$XFD,MATCH(B38,'汇率表'!$A:$A,0),MATCH(N38,'汇率表'!$1:$1,0)) -> 6.9194 | K38: =I38-J38 -> 0.2006 | L38: TB期初本位币及JE滚动后账面余额÷月末原币余额反推 | M38: CNY | N38: USD
A39: 未实现 | B39: 2026-03-31 | D39: SZ01 | E39: 01.12010.0000.0000.0000 应收账款 | F39: EUR→CNY | G39: 53800 | H39: 421254 | I39: =H39/G39 -> 7.83 | J39: =INDEX('汇率表'!$A:$XFD,MATCH(B39,'汇率表'!$A:$A,0),MATCH(N39,'汇率表'!$1:$1,0)) -> 7.9302 | K39: =I39-J39 -> -0.1002 | L39: TB期初本位币及JE滚动后账面余额÷月末原币余额反推 | M39: CNY | N39: EUR
A40: 未实现 | B40: 2026-03-31 | D40: SZ01 | E40: 01.12010.0000.0000.0000 应收账款 | F40: HKD→CNY | G40: 30000 | H40: 27300 | I40: =H40/G40 -> 0.91 | J40: =INDEX('汇率表'!$A:$XFD,MATCH(B40,'汇率表'!$A:$A,0),MATCH(N40,'汇率表'!$1:$1,0)) -> 0.88295 | K40: =I40-J40 -> 0.02705 | L40: TB期初本位币及JE滚动后账面余额÷月末原币余额反推 | M40: CNY | N40: HKD
...

Sheet 汇率表
A1: 日期 | B1: AED | C1: AUD | D1: CAD | E1: CHF | F1: CNY | G1: DKK | H1: EUR | I1: GBP | J1: HKD | K1: HUF | L1: JPY | M1: KRW | N1: MOP | O1: MXN | P1: MYR | Q1: NOK | R1: NZD | S1: PLN | T1: RUB | U1: SAR | V1: SEK | W1: SGD | X1: THB | Y1: TRY | Z1: USD | AA1: ZAR | AC1: 本次审计汇率来源
A2: 2025-11-27 | B2: 1.9256692 | C2: 4.6134 | D2: 5.0378 | E2: 8.8005 | F2: 1 | G2: 1.0986596 | H2: 8.2056 | I2: 9.3671 | J2: 0.90998 | K2: 0.021477894 | L2: 0.045267 | M2: 0.0048146365 | N2: 0.8828463 | O2: 0.38563881 | P2: 1.7108933 | Q2: 0.69352937 | R2: 4.0339 | S2: 1.9385856 | T2: 0.090088467 | U2: 1.8857962 | V2: 0.74526755 | W2: 5.4565 | X2: 0.21959682 | Y2: 0.16663862 | Z2: 7.0779 | AA2: 0.41272855 | AC2: 程序内置牌价表（国家外汇管理局人民币汇率中间价，2022-11-28~2026-08-31，随程序打包；超期区间自动回落在线抓取）
A3: 2025-11-28 | B3: 1.9268937 | C3: 4.6243 | D3: 5.046 | E3: 8.7971 | F3: 1 | G3: 1.0990219 | H3: 8.2078 | I3: 9.3697 | J3: 0.9099 | K3: 0.021522455 | L3: 0.045293 | M3: 0.0048360576 | N3: 0.88269044 | O3: 0.38583224 | P3: 1.7139723 | Q3: 0.69657286 | R3: 4.0533 | S3: 1.9417476 | T3: 0.090797657 | U3: 1.8865077 | V3: 0.74710497 | W3: 5.4589 | X3: 0.2196547 | Y3: 0.16657422 | Z3: 7.0789 | AA3: 0.41262637
A4: 2025-11-29 | B4: 1.9268937 | C4: 4.6243 | D4: 5.046 | E4: 8.7971 | F4: 1 | G4: 1.0990219 | H4: 8.2078 | I4: 9.3697 | J4: 0.9099 | K4: 0.021522455 | L4: 0.045293 | M4: 0.0048360576 | N4: 0.88269044 | O4: 0.38583224 | P4: 1.7139723 | Q4: 0.69657286 | R4: 4.0533 | S4: 1.9417476 | T4: 0.090797657 | U4: 1.8865077 | V4: 0.74710497 | W4: 5.4589 | X4: 0.2196547 | Y4: 0.16657422 | Z4: 7.0789 | AA4: 0.41262637
A5: 2025-11-30 | B5: 1.9268937 | C5: 4.6243 | D5: 5.046 | E5: 8.7971 | F5: 1 | G5: 1.0990219 | H5: 8.2078 | I5: 9.3697 | J5: 0.9099 | K5: 0.021522455 | L5: 0.045293 | M5: 0.0048360576 | N5: 0.88269044 | O5: 0.38583224 | P5: 1.7139723 | Q5: 0.69657286 | R5: 4.0533 | S5: 1.9417476 | T5: 0.090797657 | U5: 1.8865077 | V5: 0.74710497 | W5: 5.4589 | X5: 0.2196547 | Y5: 0.16657422 | Z5: 7.0789 | AA5: 0.41262637
A6: 2025-12-01 | B6: 1.9255209 | C6: 4.6302 | D6: 5.0621 | E6: 8.8013 | F6: 1 | G6: 1.0985389 | H6: 8.2052 | I6: 9.3616 | J6: 0.90877 | K6: 0.021500568 | L6: 0.045331 | M6: 0.0048192771 | N6: 0.88160099 | O6: 0.38678734 | P6: 1.7125927 | Q6: 0.69920291 | R6: 4.0535 | S6: 1.9374588 | T6: 0.091256696 | U6: 1.8854051 | V6: 0.74850299 | W6: 5.4569 | X6: 0.22010917 | Y6: 0.16644834 | Z6: 7.0759 | AA6: 0.41324022
A7: 2025-12-02 | B7: 1.9262998 | C7: 4.6292 | D7: 5.0539 | E7: 8.7915 | F7: 1 | G7: 1.0995052 | H7: 8.2113 | I7: 9.3451 | J7: 0.9088 | K7: 0.021563714 | L7: 0.045495 | M7: 0.0048095421 | N7: 0.88191199 | O7: 0.38647343 | P7: 1.7131208 | Q7: 0.69837279 | R7: 4.0512 | S7: 1.942351 | T7: 0.091027427 | U7: 1.8849786 | V7: 0.74833495 | W7: 5.4576 | X7: 0.22106287 | Y7: 0.16668722 | Z7: 7.0794 | AA7: 0.41399296
A8: 2025-12-03 | B8: 1.9245944 | C8: 4.6437 | D8: 5.0589 | E8: 8.8047 | F8: 1 | G8: 1.1004732 | H8: 8.221 | I8: 9.3429 | J8: 0.90897 | K8: 0.021577254 | L8: 0.04536 | M8: 0.0048144047 | N8: 0.88214538 | O8: 0.38677238 | P8: 1.7116547 | Q8: 0.69793412 | R8: 4.0567 | S8: 1.9417476 | T8: 0.091262526 | U8: 1.8830973 | V8: 0.74985003 | W8: 5.4544 | X8: 0.22092124 | Y8: 0.16641759 | Z8: 7.0754 | AA8: 0.41312071
A9: 2025-12-04 | B9: 1.9215618 | C9: 4.6586 | D9: 5.0597 | E9: 8.8252 | F9: 1 | G9: 1.1025358 | H9: 8.2373 | I9: 9.4207 | J9: 0.90891 | K9: 0.021635843 | L9: 0.045468 | M9: 0.0048139412 | N9: 0.88198977 | O9: 0.38608548 | P9: 1.7142074 | Q9: 0.70126227 | R9: 4.0715 | S9: 1.9498499 | T9: 0.091377609 | U9: 1.8808306 | V9: 0.75284198 | W9: 5.4573 | X9: 0.22134667 | Y9: 0.16629915 | Z9: 7.0733 | AA9: 0.41430169
A10: 2025-12-05 | B10: 1.9258917 | C10: 4.6754 | D10: 5.0682 | E10: 8.8016 | F10: 1 | G10: 1.102779 | H10: 8.2376 | I10: 9.4269 | J10: 0.90906 | K10: 0.021508198 | L10: 0.045597 | M10: 0.0047991553 | N10: 0.88261253 | O10: 0.38791264 | P10: 1.7198383 | Q10: 0.6993007 | R10: 4.0767 | S10: 1.9453361 | T10: 0.092223698 | U10: 1.8847654 | V10: 0.7505817 | W10: 5.4573 | X10: 0.22079442 | Y10: 0.16645139 | Z10: 7.0749 | AA10: 0.41637174
A11: 2025-12-06 | B11: 1.9258917 | C11: 4.6754 | D11: 5.0682 | E11: 8.8016 | F11: 1 | G11: 1.102779 | H11: 8.2376 | I11: 9.4269 | J11: 0.90906 | K11: 0.021508198 | L11: 0.045597 | M11: 0.0047991553 | N11: 0.88261253 | O11: 0.38791264 | P11: 1.7198383 | Q11: 0.6993007 | R11: 4.0767 | S11: 1.9453361 | T11: 0.092223698 | U11: 1.8847654 | V11: 0.7505817 | W11: 5.4573 | X11: 0.22079442 | Y11: 0.16645139 | Z11: 7.0749 | AA11: 0.41637174
A12: 2025-12-07 | B12: 1.9258917 | C12: 4.6754 | D12: 5.0682 | E12: 8.8016 | F12: 1 | G12: 1.102779 | H12: 8.2376 | I12: 9.4269 | J12: 0.90906 | K12: 0.021508198 | L12: 0.045597 | M12: 0.0047991553 | N12: 0.88261253 | O12: 0.38791264 | P12: 1.7198383 | Q12: 0.6993007 | R12: 4.0767 | S12: 1.9453361 | T12: 0.092223698 | U12: 1.8847654 | V12: 0.7505817 | W12: 5.4573 | X12: 0.22079442 | Y12: 0.16645139 | Z12: 7.0749 | AA12: 0.41637174
A13: 2025-12-08 | B13: 1.9258917 | C13: 4.6954 | D13: 5.1153 | E13: 8.7914 | F13: 1 | G13: 1.102779 | H13: 8.2374 | I13: 9.4271 | J13: 0.90919 | K13: 0.021581771 | L13: 0.045563 | M13: 0.0048051511 | N13: 0.8822232 | O13: 0.38919592 | P13: 1.720075 | Q13: 0.6997411 | R13: 4.0861 | S13: 1.9476852 | T13: 0.092470155 | U13: 1.8846234 | V13: 0.75261534 | W13: 5.4599 | X13: 0.22161647 | Y13: 0.16623418 | Z13: 7.0764 | AA13: 0.41771094
A14: 2025-12-09 | B14: 1.9264853 | C14: 4.688 | D14: 5.1092 | E14: 8.7713 | F14: 1 | G14: 1.102779 | H14: 8.2372 | I14: 9.4298 | J14: 0.90981 | K14: 0.021416119 | L14: 0.045391 | M14: 0.004812088 | N14: 0.88331419 | O14: 0.3874017 | P14: 1.7194835 | Q14: 0.69895855 | R14: 4.0869 | S14: 1.9435213 | T14: 0.09218714 | U14: 1.885334 | V14: 0.75318219 | W14: 5.4532 | X14: 0.22171966 | Y14: 0.16631214 | Z14: 7.0773 | AA14: 0.41526515
... A217: 2026-06-30 | B217: 1.8510634 | C217: 4.6804 | D217: 4.7847 | E217: 8.4228 | F217: 1 | G217: 1.039177 | H217: 7.7671 | I217: 9.0145 | J217: 0.86855 | K217: 0.021961177 | L217: 0.042045 | M217: 0.0044029588 | N217: 0.84324142 | O217: 0.38968124 | P217: 1.6734161 | Q217: 0.68493151 | R217: 3.8414 | S217: 1.8121195 | T217: 0.088266707 | U217: 1.8103807 | V217: 0.70032915 | W217: 5.2605 | X217: 0.20424419 | Y217: 0.14580788 | Z217: 6.8109 | AA217: 0.41440471
