Workbook

Sheet 审计结论
A1: 项目 | B1: 结果
A2: 公司/核算主体 | B2: 默认主体
A3: 报告期间 | B3: 2026-01-01 至 2026-06-30
A4: 测算范围 | B4: 已实现＋未实现
A5: 已实现汇兑损益测算 | B5: =SUMIF('汇兑损益测算明细'!$C:$C,"已实现",'汇兑损益测算明细'!$P:$P) -> -14206.473
A6: 未实现汇兑损益测算 | B6: =SUM('未实现汇兑损益测算'!$L:$L) -> 130910.07
A7: 审计测算合计 | B7: =SUM(B5:B6) -> 116703.6
A8: 客户账面汇兑损益净额（未区分已实现/未实现） | B8: -7930
A9: 测算与客户账面差异 | B9: =B7-B8 -> 124633.6
A10: 待复核项目（账面金额） | B10: =SUMIF('汇兑损益测算明细'!$C:$C,"待复核",'汇兑损益测算明细'!$P:$P) -> 2400
A11: 差异率 | B11: =IFERROR(ABS(B9/B8),0) -> 15.716721
A12: 审计结论 | B12: =IF(ABS(B8)<0.01,"无法判断",IF(B11<0.05,"通过","不通过")) -> 不通过
A13: 限制与提示 | B13: 尚有2张凭证需披露，其中不构成汇兑事项 2 张、账面汇差 2400.00（结构上不含外币货币性项目，详见「汇兑事项复核」页，属科目使用问题，建议重分类复核）；账面金额见B10；详见“汇兑事项复核”。

Sheet 汇兑损益测算明细
A1: 日期 | B1: 凭证匹配ID | C1: 测算类型 | D1: 待复核分路 | E1: 摘要 | F1: 科目代码 | G1: 原始科目名称 | H1: 币种 | I1: JE原币金额 | J1: JE本位币金额 | K1: 是否测算行 | L1: 测算原币金额 | M1: 测算采用汇率 | N1: 测算前账面金额 | O1: 审计测算金额 | P1: 测算/待复核金额 | Q1: 计算逻辑 | R1: 测算方法与数据来源 | S1: JE源文件行号 | T1: 余额 | U1: 余额方向 | V1: 借方原币 | W1: 借方本位币 | X1: 凭证字号 | Y1: 币种 | Z1: 摘要 | AA1: 日期 | AB1: 汇率 | AC1: 科目名称 | AD1: 科目编码 | AE1: 贷方原币 | AF1: 贷方本位币
A2: 2026-01-12 | B2: 默认主体-2026-01-12-记-0004 | C2: 已实现 | E2: 收到美国客户A货款 | F2: 1002.02 | G2: 美元户 | H2: 美元 | I2: 100000 | J2: 712000 | K2: 是 | L2: 100000 | M2: 7.0108 | N2: 708181.54 | O2: =L2*M2 -> 701080 | P2: =N2-O2 -> 7101.5385 | Q2: 账面金额－审计金额 | R2: 已实现：滚动审计本位币基础与本次结算价值比较；汇率来源：国家外汇管理局人民币汇率中间价查询（数据由中国外汇交易中心公布）；央行交易日中间价：7.010800 | S2: 11 | T2: 912000 | U2: 借 | V2: 100000 | W2: 712000 | X2: 记-0004 | Y2: 美元 | Z2: 收到美国客户A货款 | AA2: 2026-01-12 | AB2: 7.12 | AC2: 美元户 | AD2: 1002.02
A3: 2026-01-12 | B3: 默认主体-2026-01-12-记-0004 | C3: 已实现 | E3: 收到美国客户A货款 | F3: 1122.02 | G3: 应收账款-美元客户 | H3: 美元 | I3: -100000 | J3: -712000 | K3: 否 | S3: 12 | T3: 1032000 | U3: 借 | X3: 记-0004 | Y3: 美元 | Z3: 收到美国客户A货款 | AA3: 2026-01-12 | AB3: 7.12 | AC3: 应收账款-美元客户 | AD3: 1122.02 | AE3: 100000 | AF3: 712000
A4: 2026-01-22 | B4: 默认主体-2026-01-22-记-0010 | C4: 已实现 | E4: 支付美元供应商货款 | F4: 2202.02 | G4: 应付账款-美元供应商 | H4: 美元 | I4: 50000 | J4: 356000 | K4: 是 | L4: 50000 | M4: 7.0019 | N4: 354597.5 | O4: =L4*M4 -> 350095 | P4: =O4-N4 -> -4502.5 | Q4: 审计金额－账面金额 | R4: 已实现：滚动审计本位币基础与本次结算价值比较；汇率来源：国家外汇管理局人民币汇率中间价查询（数据由中国外汇交易中心公布）；央行交易日中间价：7.001900 | S4: 25 | T4: 251200 | U4: 贷 | V4: 50000 | W4: 356000 | X4: 记-0010 | Y4: 美元 | Z4: 支付美元供应商货款 | AA4: 2026-01-22 | AB4: 7.12 | AC4: 应付账款-美元供应商 | AD4: 2202.02
A5: 2026-01-22 | B5: 默认主体-2026-01-22-记-0010 | C5: 已实现 | E5: 支付美元供应商货款 | F5: 1002.02 | G5: 美元户 | H5: 美元 | I5: -50000 | J5: -356000 | K5: 否 | S5: 26 | T5: 556000 | U5: 借 | X5: 记-0010 | Y5: 美元 | Z5: 支付美元供应商货款 | AA5: 2026-01-22 | AB5: 7.12 | AC5: 美元户 | AD5: 1002.02 | AE5: 50000 | AF5: 356000
A6: 2026-01-24 | B6: 默认主体-2026-01-24-记-0012 | C6: 已实现 | E6: 支付香港货代运费 | F6: 2202.03 | G6: 应付账款-港币供应商 | H6: 港币 | I6: 40000 | J6: 36400 | K6: 是 | L6: 40000 | M6: 0.89676 | N6: 36337.694 | O6: =L6*M6 -> 35870.4 | P6: =O6-N6 -> -467.29412 | Q6: 审计金额－账面金额 | R6: 已实现：滚动审计本位币基础与本次结算价值比较；汇率来源：国家外汇管理局人民币汇率中间价查询（数据由中国外汇交易中心公布）；央行交易日中间价：0.896760 | S6: 29 | T6: 300000 | U6: 贷 | V6: 40000 | W6: 36400 | X6: 记-0012 | Y6: 港币 | Z6: 支付香港货代运费 | AA6: 2026-01-24 | AB6: 0.91 | AC6: 应付账款-港币供应商 | AD6: 2202.03
A7: 2026-01-24 | B7: 默认主体-2026-01-24-记-0012 | C7: 已实现 | E7: 支付香港货代运费 | F7: 1002.03 | G7: 港币户 | H7: 港币 | I7: -40000 | J7: -36400 | K7: 否 | S7: 30 | T7: 463600 | U7: 借 | X7: 记-0012 | Y7: 港币 | Z7: 支付香港货代运费 | AA7: 2026-01-24 | AB7: 0.91 | AC7: 港币户 | AD7: 1002.03 | AE7: 40000 | AF7: 36400
A8: 2026-01-25 | B8: 默认主体-2026-01-25-记-0013 | C8: 已实现 | E8: 美元结汇 | F8: 1002.01 | G8: 人民币户 | H8: 人民币 | I8: 0 | J8: 429000 | K8: 是 | L8: 60000 | M8: 7.15 | N8: 425996.4 | O8: =L8*M8 -> 429000 | P8: =N8-O8 -> -3003.6 | Q8: 账面金额－审计金额 | R8: 已实现：滚动审计本位币基础与本次结算价值比较；汇率来源：国家外汇管理局人民币汇率中间价查询（数据由中国外汇交易中心公布）；央行交易日中间价：6.992900 | S8: 31 | T8: 3844800 | U8: 借 | W8: 429000 | X8: 记-0013 | Y8: 人民币 | Z8: 美元结汇 | AA8: 2026-01-25 | AC8: 人民币户 | AD8: 1002.01
A9: 2026-01-25 | B9: 默认主体-2026-01-25-记-0013 | C9: 已实现 | E9: 美元结汇 | F9: 1002.02 | G9: 美元户 | H9: 美元 | I9: -60000 | J9: -427200 | K9: 否 | S9: 32 | T9: 128800 | U9: 借 | X9: 记-0013 | Y9: 美元 | Z9: 美元结汇 | AA9: 2026-01-25 | AB9: 7.12 | AC9: 美元户 | AD9: 1002.02 | AE9: 60000 | AF9: 427200
A10: 2026-01-25 | B10: 默认主体-2026-01-25-记-0013 | C10: 已实现 | E10: 美元结汇 | F10: 6603.02 | G10: 财务费用-汇兑损益 | H10: 人民币 | I10: 0 | J10: -1800 | K10: 否 | S10: 33 | T10: 1800 | U10: 贷 | X10: 记-0013 | Y10: 人民币 | Z10: 美元结汇 | AA10: 2026-01-25 | AC10: 财务费用-汇兑损益 | AD10: 6603.02 | AF10: 1800
A11: 2026-01-26 | B11: 默认主体-2026-01-26-记-0014 | C11: 已实现 | E11: 购汇美元 | F11: 1002.02 | G11: 美元户 | H11: 美元 | I11: 30000 | J11: 213600 | K11: 是 | L11: 30000 | M11: 6.9843 | N11: 209529 | O11: =L11*M11 -> 209529 | P11: =O11-N11 -> 4671 | Q11: 审计金额－账面金额 | R11: 购汇：实际支付本位币减去交易日官方牌价折算额；汇率来源：国家外汇管理局人民币汇率中间价查询（数据由中国外汇交易中心公布）；央行交易日中间价：6.984300 | S11: 34 | T11: 342400 | U11: 借 | V11: 30000 | W11: 213600 | X11: 记-0014 | Y11: 美元 | Z11: 购汇美元 | AA11: 2026-01-26 | AB11: 7.12 | AC11: 美元户 | AD11: 1002.02
A12: 2026-01-26 | B12: 默认主体-2026-01-26-记-0014 | C12: 已实现 | E12: 购汇美元 | F12: 1002.01 | G12: 人民币户 | H12: 人民币 | I12: 0 | J12: -214200 | K12: 否 | S12: 35 | T12: 3630600 | U12: 借 | X12: 记-0014 | Y12: 人民币 | Z12: 购汇美元 | AA12: 2026-01-26 | AC12: 人民币户 | AD12: 1002.01 | AF12: 214200
A13: 2026-01-26 | B13: 默认主体-2026-01-26-记-0014 | C13: 已实现 | E13: 购汇美元 | F13: 6603.02 | G13: 财务费用-汇兑损益 | H13: 人民币 | I13: 0 | J13: 600 | K13: 否 | S13: 36 | T13: 1200 | U13: 贷 | W13: 600 | X13: 记-0014 | Y13: 人民币 | Z13: 购汇美元 | AA13: 2026-01-26 | AC13: 财务费用-汇兑损益 | AD13: 6603.02
A14: 2026-02-12 | B14: 默认主体-2026-02-12-记-0022 | C14: 已实现 | E14: 收到美国客户A货款 | F14: 1002.02 | G14: 美元户 | H14: usd | I14: 100000 | J14: 712000 | K14: 是 | L14: 100000 | M14: 6.9457 | N14: 696607.2 | O14: =L14*M14 -> 694570 | P14: =N14-O14 -> 2037.2 | Q14: 账面金额－审计金额 | R14: 已实现：滚动审计本位币基础与本次结算价值比较；汇率来源：国家外汇管理局人民币汇率中间价查询（数据由中国外汇交易中心公布）；央行交易日中间价：6.945700 | S14: 59 | T14: 1125600 | U14: 借 | V14: 100000 | W14: 712000 | X14: 记-0022 | Y14: usd | Z14: 收到美国客户A货款 | AA14: 2026-02-12 | AB14: 7.12 | AC14: 美元户 | AD14: 1002.02
A15: 2026-02-12 | B15: 默认主体-2026-02-12-记-0022 | C15: 已实现 | E15: 收到美国客户A货款 | F15: 1122.02 | G15: 应收账款-美元客户 | H15: 美元 | I15: -100000 | J15: -712000 | K15: 否 | S15: 60 | T15: 889600 | U15: 借 | X15: 记-0022 | Y15: 美元 | Z15: 收到美国客户A货款 | AA15: 2026-02-12 | AB15: 7.12 | AC15: 应收账款-美元客户 | AD15: 1122.02 | AE15: 100000 | AF15: 712000
A16: 2026-02-17 | B16: 默认主体-2026-02-17-记-0026 | C16: 已实现 | E16: 收到欧元客户货款并结汇 | F16: 1002.01 | G16: 人民币户 | H16: 人民币 | I16: 0 | J16: 196250 | K16: 是 | L16: 25000 | M16: 7.85 | N16: 208110 | O16: =L16*M16 -> 196250 | P16: =N16-O16 -> 11860 | Q16: 账面金额－审计金额 | R16: 已实现：滚动审计本位币基础与本次结算价值比较；汇率来源：国家外汇管理局人民币汇率中间价查询（数据由中国外汇交易中心公布）；央行交易日中间价：8.219500 | S16: 68 | T16: 3603950 | U16: 借 | W16: 196250 | X16: 记-0026 | Y16: 人民币 | Z16: 收到欧元客户货款并结汇 | AA16: 2026-02-17 | AC16: 人民币户 | AD16: 1002.01
A17: 2026-02-17 | B17: 默认主体-2026-02-17-记-0026 | C17: 已实现 | E17: 收到欧元客户货款并结汇 | F17: 1122.03 | G17: 应收账款-欧元客户 | H17: 欧元 | I17: -25000 | J17: -195750 | K17: 否 | S17: 69 | T17: 45750 | U17: 贷 | X17: 记-0026 | Y17: 欧元 | Z17: 收到欧元客户货款并结汇 | AA17: 2026-02-17 | AB17: 7.83 | AC17: 应收账款-欧元客户 | AD17: 1122.03 | AE17: 25000 | AF17: 195750
A18: 2026-02-17 | B18: 默认主体-2026-02-17-记-0026 | C18: 已实现 | E18: 收到欧元客户货款并结汇 | F18: 6603.02 | G18: 财务费用-汇兑损益 | H18: 人民币 | I18: 0 | J18: -500 | K18: 否 | S18: 70 | T18: 500 | U18: 贷 | X18: 记-0026 | Y18: 人民币 | Z18: 收到欧元客户货款并结汇 | AA18: 2026-02-17 | AC18: 财务费用-汇兑损益 | AD18: 6603.02 | AF18: 500
A19: 2026-02-22 | B19: 默认主体-2026-02-22-记-0029 | C19: 已实现 | E19: 支付美元供应商货款 | F19: 2202.02 | G19: 应付账款-美元供应商 | H19: 美元 | I19: 30000 | J19: 213600 | K19: 是 | L19: 30000 | M19: 6.9398 | N19: 208887.91 | O19: =L19*M19 -> 208194 | P19: =O19-N19 -> -693.91304 | Q19: 审计金额－账面金额 | R19: 已实现：滚动审计本位币基础与本次结算价值比较；汇率来源：国家外汇管理局人民币汇率中间价查询（数据由中国外汇交易中心公布）；央行交易日中间价：6.939800 | S19: 76 | T19: 322400 | U19: 贷 | V19: 30000 | W19: 213600 | X19: 记-0029 | Y19: 美元 | Z19: 支付美元供应商货款 | AA19: 2026-02-22 | AB19: 7.12 | AC19: 应付账款-美元供应商 | AD19: 2202.02
A20: 2026-02-22 | B20: 默认主体-2026-02-22-记-0029 | C20: 已实现 | E20: 支付美元供应商货款 | F20: 1002.02 | G20: 美元户 | H20: 美元 | I20: -30000 | J20: -213600 | K20: 否 | S20: 77 | T20: 912000 | U20: 借 | X20: 记-0029 | Y20: 美元 | Z20: 支付美元供应商货款 | AA20: 2026-02-22 | AB20: 7.12 | AC20: 美元户 | AD20: 1002.02 | AE20: 30000 | AF20: 213600
A21: 2026-02-24 | B21: 默认主体-2026-02-24-记-0031 | C21: 已实现 | E21: 支付香港货代运费 | F21: 2202.03 | G21: 应付账款-港币供应商 | H21: 港币 | I21: 30000 | J21: 27300 | K21: 是 | L21: 30000 | M21: 0.88773 | N21: 26765.645 | O21: =L21*M21 -> 26631.9 | P21: =O21-N21 -> -133.74545 | Q21: 审计金额－账面金额 | R21: 已实现：滚动审计本位币基础与本次结算价值比较；汇率来源：国家外汇管理局人民币汇率中间价查询（数据由中国外汇交易中心公布）；央行交易日中间价：0.887730 | S21: 80 | T21: 300000 | U21: 贷 | V21: 30000 | W21: 27300 | X21: 记-0031 | Y21: 港币 | Z21: 支付香港货代运费 | AA21: 2026-02-24 | AB21: 0.91 | AC21: 应付账款-港币供应商 | AD21: 2202.03
A22: 2026-02-24 | B22: 默认主体-2026-02-24-记-0031 | C22: 已实现 | E22: 支付香港货代运费 | F22: 1002.03 | G22: 港币户 | H22: 港币 | I22: -30000 | J22: -27300 | K22: 否 | S22: 81 | T22: 436300 | U22: 借 | X22: 记-0031 | Y22: 港币 | Z22: 支付香港货代运费 | AA22: 2026-02-24 | AB22: 0.91 | AC22: 港币户 | AD22: 1002.03 | AE22: 30000 | AF22: 27300
A23: 2026-02-25 | B23: 默认主体-2026-02-25-记-0032 | C23: 已实现 | E23: 美元结汇 | F23: 1002.01 | G23: 人民币户 | H23: 人民币 | I23: 0 | J23: 285600 | K23: 是 | L23: 40000 | M23: 7.14 | N23: 278526.53 | O23: =L23*M23 -> 285600 | P23: =N23-O23 -> -7073.4667 | Q23: 账面金额－审计金额 | R23: 已实现：滚动审计本位币基础与本次结算价值比较；汇率来源：国家外汇管理局人民币汇率中间价查询（数据由中国外汇交易中心公布）；央行交易日中间价：6.932100 | S23: 82 | T23: 3889550 | U23: 借 | W23: 285600 | X23: 记-0032 | Y23: 人民币 | Z23: 美元结汇 | AA23: 2026-02-25 | AC23: 人民币户 | AD23: 1002.01
A24: 2026-02-25 | B24: 默认主体-2026-02-25-记-0032 | C24: 已实现 | E24: 美元结汇 | F24: 1002.02 | G24: 美元户 | H24: 美元 | I24: -40000 | J24: -284800 | K24: 否 | S24: 83 | T24: 627200 | U24: 借 | X24: 记-0032 | Y24: 美元 | Z24: 美元结汇 | AA24: 2026-02-25 | AB24: 7.12 | AC24: 美元户 | AD24: 1002.02 | AE24: 40000 | AF24: 284800
A25: 2026-02-25 | B25: 默认主体-2026-02-25-记-0032 | C25: 已实现 | E25: 美元结汇 | F25: 6603.02 | G25: 财务费用-汇兑损益 | H25: 人民币 | I25: 0 | J25: -800 | K25: 否 | S25: 84 | T25: 1300 | U25: 贷 | X25: 记-0032 | Y25: 人民币 | Z25: 美元结汇 | AA25: 2026-02-25 | AC25: 财务费用-汇兑损益 | AD25: 6603.02 | AF25: 800
A26: 2026-03-12 | B26: 默认主体-2026-03-12-记-0040 | C26: 已实现 | E26: 收到美国客户A货款 | F26: 1002.02 | G26: 美元户 | H26: 美元 | I26: 120000 | J26: 854400 | K26: 是 | L26: 120000 | M26: 6.8959 | N26: 829880.8 | O26: =L26*M26 -> 827508 | P26: =N26-O26 -> 2372.8 | Q26: 账面金额－审计金额 | R26: 已实现：滚动审计本位币基础与本次结算价值比较；汇率来源：国家外汇管理局人民币汇率中间价查询（数据由中国外汇交易中心公布）；央行交易日中间价：6.895900 | S26: 108 | T26: 1481600 | U26: 借 | V26: 120000 | W26: 854400 | X26: 记-0040 | Y26: 美元 | Z26: 收到美国客户A货款 | AA26: 2026-03-12 | AB26: 7.12 | AC26: 美元户 | AD26: 1002.02
A27: 2026-03-12 | B27: 默认主体-2026-03-12-记-0040 | C27: 已实现 | E27: 收到美国客户A货款 | F27: 1122.02 | G27: 应收账款-美元客户 | H27: 美元 | I27: -120000 | J27: -854400 | K27: 否 | S27: 109 | T27: 1459200 | U27: 借 | X27: 记-0040 | Y27: 美元 | Z27: 收到美国客户A货款 | AA27: 2026-03-12 | AB27: 7.12 | AC27: 应收账款-美元客户 | AD27: 1122.02 | AE27: 120000 | AF27: 854400
A28: 2026-03-13 | B28: 默认主体-2026-03-13-记-0041 | C28: 待复核 | D28: 非货币性项目/异常复核 | E28: 购汇日元预付日本供应商货款 | F28: 1123.02 | G28: 预付款项-日元 | H28: 日元 | I28: 2000000 | J28: 96400 | K28: 是 | L28: 0 | M28: 0 | N28: 1200 | P28: =N28 -> 1200 | Q28: 账面金额仅供参考，不纳入审计测算 | R28: 对方科目为预付款、存货、固定资产等非货币性项目，不产生外币汇兑损益；账面汇差建议重分类复核 | S28: 110 | T28: 5096400 | U28: 借 | V28: 2000000 | W28: 96400 | X28: 记-0041 | Y28: 日元 | Z28: 购汇日元预付日本供应商货款 | AA28: 2026-03-13 | AB28: 0.0482 | AC28: 预付款项-日元 | AD28: 1123.02
A29: 2026-03-13 | B29: 默认主体-2026-03-13-记-0041 | C29: 待复核 | D29: 非货币性项目/异常复核 | E29: 购汇日元预付日本供应商货款 | F29: 1002.01 | G29: 人民币户 | H29: 人民币 | I29: 0 | J29: -97600 | K29: 否 | S29: 111 | T29: 3492150 | U29: 借 | X29: 记-0041 | Y29: 人民币 | Z29: 购汇日元预付日本供应商货款 | AA29: 2026-03-13 | AC29: 人民币户 | AD29: 1002.01 | AF29: 97600
A30: 2026-03-13 | B30: 默认主体-2026-03-13-记-0041 | C30: 待复核 | D30: 非货币性项目/异常复核 | E30: 购汇日元预付日本供应商货款 | F30: 6603.02 | G30: 财务费用-汇兑损益 | H30: 人民币 | I30: 0 | J30: 1200 | K30: 否 | S30: 112 | T30: 1200 | U30: 借 | W30: 1200 | X30: 记-0041 | Y30: 人民币 | Z30: 购汇日元预付日本供应商货款 | AA30: 2026-03-13 | AC30: 财务费用-汇兑损益 | AD30: 6603.02
A31: 2026-03-22 | B31: 默认主体-2026-03-22-记-0048 | C31: 已实现 | E31: 支付美元供应商货款 | F31: 2202.02 | G31: 应付账款-美元供应商 | H31: 美元 | I31: 50000 | J31: 356000 | K31: 是 | L31: 50000 | M31: 6.8898 | N31: 345771.92 | O31: =L31*M31 -> 344490 | P31: =O31-N31 -> -1281.9231 | Q31: 审计金额－账面金额 | R31: 已实现：滚动审计本位币基础与本次结算价值比较；汇率来源：国家外汇管理局人民币汇率中间价查询（数据由中国外汇交易中心公布）；央行交易日中间价：6.889800 | S31: 127 | T31: 393600 | U31: 贷 | V31: 50000 | W31: 356000 | X31: 记-0048 | Y31: 美元 | Z31: 支付美元供应商货款 | AA31: 2026-03-22 | AB31: 7.12 | AC31: 应付账款-美元供应商 | AD31: 2202.02
A32: 2026-03-22 | B32: 默认主体-2026-03-22-记-0048 | C32: 已实现 | E32: 支付美元供应商货款 | F32: 1002.02 | G32: 美元户 | H32: 美元 | I32: -50000 | J32: -356000 | K32: 否 | S32: 128 | T32: 1125600 | U32: 借 | X32: 记-0048 | Y32: 美元 | Z32: 支付美元供应商货款 | AA32: 2026-03-22 | AB32: 7.12 | AC32: 美元户 | AD32: 1002.02 | AE32: 50000 | AF32: 356000
A33: 2026-03-24 | B33: 默认主体-2026-03-24-记-0050 | C33: 已实现 | E33: 支付香港货代运费 | F33: 2202.03 | G33: 应付账款-港币供应商 | H33: 港币 | I33: 40000 | J33: 36400 | K33: 是 | L33: 40000 | M33: 0.88015 | N33: 35376.188 | O33: =L33*M33 -> 35206 | P33: =O33-N33 -> -170.18824 | Q33: 审计金额－账面金额 | R33: 已实现：滚动审计本位币基础与本次结算价值比较；汇率来源：国家外汇管理局人民币汇率中间价查询（数据由中国外汇交易中心公布）；央行交易日中间价：0.880150 | S33: 131 | T33: 300000 | U33: 贷 | V33: 40000 | W33: 36400 | X33: 记-0050 | Y33: 港币 | Z33: 支付香港货代运费 | AA33: 2026-03-24 | AB33: 0.91 | AC33: 应付账款-港币供应商 | AD33: 2202.03
A34: 2026-03-24 | B34: 默认主体-2026-03-24-记-0050 | C34: 已实现 | E34: 支付香港货代运费 | F34: 1002.03 | G34: 港币户 | H34: 港币 | I34: -40000 | J34: -36400 | K34: 否 | S34: 132 | T34: 399900 | U34: 借 | X34: 记-0050 | Y34: 港币 | Z34: 支付香港货代运费 | AA34: 2026-03-24 | AB34: 0.91 | AC34: 港币户 | AD34: 1002.03 | AE34: 40000 | AF34: 36400
A35: 2026-03-25 | B35: 默认主体-2026-03-25-记-0051 | C35: 已实现 | E35: 美元结汇 | F35: 1002.01 | G35: 人民币户 | H35: 人民币 | I35: 0 | J35: 429000 | K35: 是 | L35: 60000 | M35: 7.15 | N35: 415081.09 | O35: =L35*M35 -> 429000 | P35: =N35-O35 -> -13918.909 | Q35: 账面金额－审计金额 | R35: 已实现：滚动审计本位币基础与本次结算价值比较；汇率来源：国家外汇管理局人民币汇率中间价查询（数据由中国外汇交易中心公布）；央行交易日中间价：6.891100 | S35: 133 | T35: 3836950 | U35: 借 | W35: 429000 | X35: 记-0051 | Y35: 人民币 | Z35: 美元结汇 | AA35: 2026-03-25 | AC35: 人民币户 | AD35: 1002.01
A36: 2026-03-25 | B36: 默认主体-2026-03-25-记-0051 | C36: 已实现 | E36: 美元结汇 | F36: 1002.02 | G36: 美元户 | H36: 美元 | I36: -60000 | J36: -427200 | K36: 否 | S36: 134 | T36: 698400 | U36: 借 | X36: 记-0051 | Y36: 美元 | Z36: 美元结汇 | AA36: 2026-03-25 | AB36: 7.12 | AC36: 美元户 | AD36: 1002.02 | AE36: 60000 | AF36: 427200
A37: 2026-03-25 | B37: 默认主体-2026-03-25-记-0051 | C37: 已实现 | E37: 美元结汇 | F37: 6603.02 | G37: 财务费用-汇兑损益 | H37: 人民币 | I37: 0 | J37: -1800 | K37: 否 | S37: 135 | T37: 600 | U37: 贷 | X37: 记-0051 | Y37: 人民币 | Z37: 美元结汇 | AA37: 2026-03-25 | AC37: 财务费用-汇兑损益 | AD37: 6603.02 | AF37: 1800
A38: 2026-03-26 | B38: 默认主体-2026-03-26-记-0052 | C38: 已实现 | E38: 购汇美元 | F38: 1002.02 | G38: 美元户 | H38: 美元 | I38: 30000 | J38: 213600 | K38: 是 | L38: 30000 | M38: 6.9056 | N38: 207168 | O38: =L38*M38 -> 207168 | P38: =O38-N38 -> 7032 | Q38: 审计金额－账面金额 | R38: 购汇：实际支付本位币减去交易日官方牌价折算额；汇率来源：国家外汇管理局人民币汇率中间价查询（数据由中国外汇交易中心公布）；央行交易日中间价：6.905600 | S38: 136 | T38: 912000 | U38: 借 | V38: 30000 | W38: 213600 | X38: 记-0052 | Y38: 美元 | Z38: 购汇美元 | AA38: 2026-03-26 | AB38: 7.12 | AC38: 美元户 | AD38: 1002.02
A39: 2026-03-26 | B39: 默认主体-2026-03-26-记-0052 | C39: 已实现 | E39: 购汇美元 | F39: 1002.01 | G39: 人民币户 | H39: 人民币 | I39: 0 | J39: -214200 | K39: 否 | S39: 137 | T39: 3622750 | U39: 借 | X39: 记-0052 | Y39: 人民币 | Z39: 购汇美元 | AA39: 2026-03-26 | AC39: 人民币户 | AD39: 1002.01 | AF39: 214200
A40: 2026-03-26 | B40: 默认主体-2026-03-26-记-0052 | C40: 已实现 | E40: 购汇美元 | F40: 6603.02 | G40: 财务费用-汇兑损益 | H40: 人民币 | I40: 0 | J40: 600 | K40: 否 | S40: 138 | T40: 0 | U40: 平 | W40: 600 | X40: 记-0052 | Y40: 人民币 | Z40: 购汇美元 | AA40: 2026-03-26 | AC40: 财务费用-汇兑损益 | AD40: 6603.02
...

Sheet 客户与审计汇率比较
A1: 类型 | B1: 日期/月末 | C1: 凭证号 | D1: 主体 | E1: 科目 | F1: 币种 | G1: 客户隐含汇率 | H1: 反推依据 | I1: 可靠性 | J1: 审计期初/月初汇率 | K1: 审计交易日/月末汇率 | L1: 客户与审计期初/月初汇率差 | M1: 客户与审计交易日/月末汇率差 | N1: 原币基础 | O1: 汇率基础影响 | P1: 说明
A2: 已实现 | B2: 2026-01-12 | C2: 默认主体-2026-01-12-记-0004 | D2: 默认主体 | E2: 1122.02 应收账款-美元客户 | F2: USD | G2: 7.12 | H2: JE本位币金额÷原币金额反推 | I2: 反推 | J2: 7.0288 | K2: 7.0108 | L2: 0.0912 | M2: 0.1092 | N2: 100000 | O2: -3818.4615 | P2: 已实现项目的反推值只表示JE账面隐含汇率，不表示客户明确申明的政策汇率。
A3: 已实现 | B3: 2026-01-22 | C3: 默认主体-2026-01-22-记-0010 | D3: 默认主体 | E3: 2202.02 应付账款-美元供应商 | F3: USD | G3: 7.12 | H3: JE本位币金额÷原币金额反推 | I3: 反推 | J3: 7.0288 | K3: 7.0019 | L3: 0.0912 | M3: 0.1181 | N3: 50000 | O3: -1402.5 | P3: 已实现项目的反推值只表示JE账面隐含汇率，不表示客户明确申明的政策汇率。
A4: 已实现 | B4: 2026-01-24 | C4: 默认主体-2026-01-24-记-0012 | D4: 默认主体 | E4: 2202.03 应付账款-港币供应商 | F4: HKD | G4: 0.91 | H4: JE本位币金额÷原币金额反推 | I4: 反推 | J4: 0.90322 | K4: 0.89676 | L4: 0.00678 | M4: 0.01324 | N4: 40000 | O4: -62.305882 | P4: 已实现项目的反推值只表示JE账面隐含汇率，不表示客户明确申明的政策汇率。
A5: 已实现 | B5: 2026-01-25 | C5: 默认主体-2026-01-25-记-0013 | D5: 默认主体 | E5: 1002.02 美元户 | F5: USD | G5: 7.12 | H5: JE本位币金额÷原币金额反推 | I5: 反推 | J5: 7.0288 | K5: 6.9929 | L5: 0.0912 | M5: 0.1271 | N5: 60000 | O5: -1203.6 | P5: 已实现项目的反推值只表示JE账面隐含汇率，不表示客户明确申明的政策汇率。
A6: 已实现 | B6: 2026-02-12 | C6: 默认主体-2026-02-12-记-0022 | D6: 默认主体 | E6: 1122.02 应收账款-美元客户 | F6: USD | G6: 7.12 | H6: JE本位币金额÷原币金额反推 | I6: 反推 | J6: 6.9678 | K6: 6.9457 | L6: 0.1522 | M6: 0.1743 | N6: 100000 | O6: -15392.8 | P6: 已实现项目的反推值只表示JE账面隐含汇率，不表示客户明确申明的政策汇率。
A7: 已实现 | B7: 2026-02-17 | C7: 默认主体-2026-02-17-记-0026 | D7: 默认主体 | E7: 1122.03 应收账款-欧元客户 | F7: EUR | G7: 7.83 | H7: JE本位币金额÷原币金额反推 | I7: 反推 | J7: 8.3244 | K7: 8.2195 | L7: -0.4944 | M7: -0.3895 | N7: 25000 | O7: 12360 | P7: 已实现项目的反推值只表示JE账面隐含汇率，不表示客户明确申明的政策汇率。
A8: 已实现 | B8: 2026-02-22 | C8: 默认主体-2026-02-22-记-0029 | D8: 默认主体 | E8: 2202.02 应付账款-美元供应商 | F8: USD | G8: 7.12 | H8: JE本位币金额÷原币金额反推 | I8: 反推 | J8: 6.9678 | K8: 6.9398 | L8: 0.1522 | M8: 0.1802 | N8: 30000 | O8: -4712.087 | P8: 已实现项目的反推值只表示JE账面隐含汇率，不表示客户明确申明的政策汇率。
A9: 已实现 | B9: 2026-02-24 | C9: 默认主体-2026-02-24-记-0031 | D9: 默认主体 | E9: 2202.03 应付账款-港币供应商 | F9: HKD | G9: 0.91 | H9: JE本位币金额÷原币金额反推 | I9: 反推 | J9: 0.89262 | K9: 0.88773 | L9: 0.01738 | M9: 0.02227 | N9: 30000 | O9: -534.35455 | P9: 已实现项目的反推值只表示JE账面隐含汇率，不表示客户明确申明的政策汇率。
A10: 已实现 | B10: 2026-02-25 | C10: 默认主体-2026-02-25-记-0032 | D10: 默认主体 | E10: 1002.02 美元户 | F10: USD | G10: 7.12 | H10: JE本位币金额÷原币金额反推 | I10: 反推 | J10: 6.9678 | K10: 6.9321 | L10: 0.1522 | M10: 0.1879 | N10: 40000 | O10: -6273.4667 | P10: 已实现项目的反推值只表示JE账面隐含汇率，不表示客户明确申明的政策汇率。
A11: 已实现 | B11: 2026-03-12 | C11: 默认主体-2026-03-12-记-0040 | D11: 默认主体 | E11: 1122.02 应收账款-美元客户 | F11: USD | G11: 7.12 | H11: JE本位币金额÷原币金额反推 | I11: 反推 | J11: 6.9228 | K11: 6.8959 | L11: 0.1972 | M11: 0.2241 | N11: 120000 | O11: -24519.2 | P11: 已实现项目的反推值只表示JE账面隐含汇率，不表示客户明确申明的政策汇率。
A12: 已实现 | B12: 2026-03-22 | C12: 默认主体-2026-03-22-记-0048 | D12: 默认主体 | E12: 2202.02 应付账款-美元供应商 | F12: USD | G12: 7.12 | H12: JE本位币金额÷原币金额反推 | I12: 反推 | J12: 6.9228 | K12: 6.8898 | L12: 0.1972 | M12: 0.2302 | N12: 50000 | O12: -10228.077 | P12: 已实现项目的反推值只表示JE账面隐含汇率，不表示客户明确申明的政策汇率。
A13: 已实现 | B13: 2026-03-24 | C13: 默认主体-2026-03-24-记-0050 | D13: 默认主体 | E13: 2202.03 应付账款-港币供应商 | F13: HKD | G13: 0.91 | H13: JE本位币金额÷原币金额反推 | I13: 反推 | J13: 0.88484 | K13: 0.88015 | L13: 0.02516 | M13: 0.02985 | N13: 40000 | O13: -1023.8118 | P13: 已实现项目的反推值只表示JE账面隐含汇率，不表示客户明确申明的政策汇率。
... A27: 已实现 | B27: 2026-06-25 | C27: 默认主体-2026-06-25-记-0105 | D27: 默认主体 | E27: 1002.02 美元户 | F27: USD | G27: 7.12 | H27: JE本位币金额÷原币金额反推 | I27: 反推 | J27: 6.8176 | K27: 6.8209 | L27: 0.3024 | M27: 0.2991 | N27: 70000 | O27: -21299.25 | P27: 已实现项目的反推值只表示JE账面隐含汇率，不表示客户明确申明的政策汇率。
A28: 未实现 | B28: 2026-01-31 | D28: 默认主体 | E28: 1002.02 美元户 | F28: USD | G28: 7.12 | H28: TB期初本位币及JE滚动后账面余额÷月末原币余额反推 | I28: 反推 | K28: 6.9678 | M28: 0.1522 | N28: 220000 | O28: -33484 | P28: 客户隐含汇率仅作差异解释；审计未实现损益始终按官方月末汇率独立测算。
A29: 未实现 | B29: 2026-01-31 | D29: 默认主体 | E29: 1002.03 港币户 | F29: HKD | G29: 0.91 | H29: TB期初本位币及JE滚动后账面余额÷月末原币余额反推 | I29: 反推 | K29: 0.89262 | M29: 0.01738 | N29: 460000 | O29: -7994.8 | P29: 客户隐含汇率仅作差异解释；审计未实现损益始终按官方月末汇率独立测算。
A30: 未实现 | B30: 2026-01-31 | D30: 默认主体 | E30: 1122.02 应收账款-美元客户 | F30: USD | G30: 7.12 | H30: TB期初本位币及JE滚动后账面余额÷月末原币余额反推 | I30: 反推 | K30: 6.9678 | M30: 0.1522 | N30: 420000 | O30: -63924 | P30: 客户隐含汇率仅作差异解释；审计未实现损益始终按官方月末汇率独立测算。
A31: 未实现 | B31: 2026-01-31 | D31: 默认主体 | E31: 1122.03 应收账款-欧元客户 | F31: EUR | G31: 7.83 | H31: TB期初本位币及JE滚动后账面余额÷月末原币余额反推 | I31: 反推 | K31: 8.3244 | M31: -0.4944 | N31: 150000 | O31: 74160 | P31: 客户隐含汇率仅作差异解释；审计未实现损益始终按官方月末汇率独立测算。
A32: 未实现 | B32: 2026-01-31 | D32: 默认主体 | E32: 2202.02 应付账款-美元供应商 | F32: USD | G32: 7.12 | H32: TB期初本位币及JE滚动后账面余额÷月末原币余额反推 | I32: 反推 | K32: 6.9678 | M32: 0.1522 | N32: -190000 | O32: 28918 | P32: 客户隐含汇率仅作差异解释；审计未实现损益始终按官方月末汇率独立测算。
A33: 未实现 | B33: 2026-01-31 | D33: 默认主体 | E33: 2202.03 应付账款-港币供应商 | F33: HKD | G33: 0.91 | H33: TB期初本位币及JE滚动后账面余额÷月末原币余额反推 | I33: 反推 | K33: 0.89262 | M33: 0.01738 | N33: -300000 | O33: 5214 | P33: 客户隐含汇率仅作差异解释；审计未实现损益始终按官方月末汇率独立测算。
A34: 未实现 | B34: 2026-02-28 | D34: 默认主体 | E34: 1002.02 美元户 | F34: USD | G34: 7.12 | H34: TB期初本位币及JE滚动后账面余额÷月末原币余额反推 | I34: 反推 | K34: 6.9228 | M34: 0.1972 | N34: 260000 | O34: -51272 | P34: 客户隐含汇率仅作差异解释；审计未实现损益始终按官方月末汇率独立测算。
A35: 未实现 | B35: 2026-02-28 | D35: 默认主体 | E35: 1002.03 港币户 | F35: HKD | G35: 0.91 | H35: TB期初本位币及JE滚动后账面余额÷月末原币余额反推 | I35: 反推 | K35: 0.88484 | M35: 0.02516 | N35: 430000 | O35: -10818.8 | P35: 客户隐含汇率仅作差异解释；审计未实现损益始终按官方月末汇率独立测算。
A36: 未实现 | B36: 2026-02-28 | D36: 默认主体 | E36: 1122.02 应收账款-美元客户 | F36: USD | G36: 7.12 | H36: TB期初本位币及JE滚动后账面余额÷月末原币余额反推 | I36: 反推 | K36: 6.9228 | M36: 0.1972 | N36: 400000 | O36: -78880 | P36: 客户隐含汇率仅作差异解释；审计未实现损益始终按官方月末汇率独立测算。
A37: 未实现 | B37: 2026-02-28 | D37: 默认主体 | E37: 1122.03 应收账款-欧元客户 | F37: EUR | G37: 7.83 | H37: TB期初本位币及JE滚动后账面余额÷月末原币余额反推 | I37: 反推 | K37: 8.1208 | M37: -0.2908 | N37: 125000 | O37: 36350 | P37: 客户隐含汇率仅作差异解释；审计未实现损益始终按官方月末汇率独立测算。
A38: 未实现 | B38: 2026-02-28 | D38: 默认主体 | E38: 2202.02 应付账款-美元供应商 | F38: USD | G38: 7.12 | H38: TB期初本位币及JE滚动后账面余额÷月末原币余额反推 | I38: 反推 | K38: 6.9228 | M38: 0.1972 | N38: -200000 | O38: 39440 | P38: 客户隐含汇率仅作差异解释；审计未实现损益始终按官方月末汇率独立测算。
A39: 未实现 | B39: 2026-02-28 | D39: 默认主体 | E39: 2202.03 应付账款-港币供应商 | F39: HKD | G39: 0.91 | H39: TB期初本位币及JE滚动后账面余额÷月末原币余额反推 | I39: 反推 | K39: 0.88484 | M39: 0.02516 | N39: -300000 | O39: 7548 | P39: 客户隐含汇率仅作差异解释；审计未实现损益始终按官方月末汇率独立测算。
... A63: 未实现 | B63: 2026-06-30 | D63: 默认主体 | E63: 2202.03 应付账款-港币供应商 | F63: HKD | G63: 0.91 | H63: TB期初本位币及JE滚动后账面余额÷月末原币余额反推 | I63: 反推 | K63: 0.86855 | M63: 0.04145 | N63: -300000 | O63: 12435 | P63: 客户隐含汇率仅作差异解释；审计未实现损益始终按官方月末汇率独立测算。

Sheet 使用说明
A1: 项目 | B1: 内容
A2: 底稿用途 | B2: 汇兑损益审计重算；结果需结合业务资料与审计判断复核。
A3: 测算模式 | B3: 已实现＋未实现
A4: 汇率口径 | B4: 程序内置牌价表（国家外汇管理局人民币汇率中间价，2022-11-28~2026-08-31，随程序打包；超期区间自动回落在线抓取）
A5: 重要说明 | B5: 已实现仅按单张凭证内的资金结构识别：货币资金净额非零，且对方货币性项目净额非零；未实现按外币原币净额为零、本位币净额非零识别。汇兑损益科目、凭证类型和摘要不参与定性。

Sheet 执行摘要
A1: 项目 | B1: 内容
A2: 是否启用科目名称翻译 | B2: 否
A3: 审计测算汇兑损益 | B3: 116703.6
A4: 自动测算合计 | B4: 116703.6
A5: JE账面净额是否可区分 | B5: 是
A6: 账面汇兑损益取数来源 | B6: JE剔除损益结转后的净额
A7: 客户已入账未实现汇兑损益 | B7: 0
A8: 自动测算覆盖的账面汇兑损益 | B8: -10330
A9: 已覆盖账面已实现汇兑损益 | B9: -10330
A10: 已覆盖项目测算差异 | B10: 127033.6
A11: diagnosticMeasuredFxGainLoss | B11: 116703.6
A12: 测算与客户账面差异 | B12: 124633.6
A13: 差异率 | B13: 15.716721
A14: 是否可形成正式测算结果 | B14: 是
A15: 正式测算受限原因 | B15: []
A16: 低置信度事件数 | B16: 0
A17: 自动测算金额差异 | B17: 127033.6
A18: 零结果是否需要复核 | B18: 否
A19: notFxEventAmount | B19: 2400
A20: notFxEventCount | B20: 2
A21: 待复核项目账面金额 | B21: 2400
A22: 待复核项目数 | B22: 2
A23: pendingUnclassifiedCount | B23: 0
A24: pendingUnmeasurableCount | B24: 0
A25: 已实现测算事件数 | B25: 32
A26: 已实现汇兑损益 | B26: -14206.473
A27: 已实现测算差异 | B27: -3876.4731
A28: 勾稽是否通过 | B28: 否
A29: rollforwardIssueCount | B29: 0
A30: rollforwardPassed | B30: 是
A31: TB汇兑损益诊断金额（不作为净损益） | B31: 14650
A32: tbFxGainAmount | B32: 0
A33: TB汇兑损益发生额 | B33: -7930
A34: tbFxGainLossPresentation | B34: 已实现＋未实现
A35: tbFxLossAmount | B35: 14650
A36: tbRealizedGainLoss
A37: tbUnrealizedGainLoss
A38: 已翻译英文科目数 | B38: 0
A39: 未覆盖账面金额 | B39: 2400
A40: 未实现汇兑损益 | B40: 130910.07
...

Sheet 参数与口径
A1: 项目 | B1: 内容
A2: 报告期开始 | B2: 2026-01-01
A3: 报告期结束 | B3: 2026-06-30
A4: 测算模式 | B4: 已实现＋未实现
A5: 汇率口径 | B5: 程序内置牌价表（国家外汇管理局人民币汇率中间价，2022-11-28~2026-08-31，随程序打包；超期区间自动回落在线抓取）

Sheet JE字段映射
A1: 字段角色 | B1: 最终映射 | C1: 校验结果 | D1: 识别方式
A2: __signConvention | B2: unsigned | C2: 后端再次验证 | D2: 硬编码 + LLM复核 + 用户确认
A3: 科目编码 | B3: 科目编码 | C3: 后端再次验证 | D3: 硬编码 + LLM复核 + 用户确认
A4: 科目名称 | B4: ["科目名称"] | C4: 后端再次验证 | D4: 硬编码 + LLM复核 + 用户确认
A5: 币种 | B5: 币种 | C5: 后端再次验证 | D5: 硬编码 + LLM复核 + 用户确认
A6: 日期 | B6: 日期 | C6: 后端再次验证 | D6: 硬编码 + LLM复核 + 用户确认
A7: direction | B7: 余额方向 | C7: 后端再次验证 | D7: 硬编码 + LLM复核 + 用户确认
A8: foreignCredit | B8: 贷方原币 | C8: 后端再次验证 | D8: 硬编码 + LLM复核 + 用户确认
A9: foreignDebit | B9: 借方原币 | C9: 后端再次验证 | D9: 硬编码 + LLM复核 + 用户确认
A10: functionalCredit | B10: 贷方本位币 | C10: 后端再次验证 | D10: 硬编码 + LLM复核 + 用户确认
A11: functionalDebit | B11: 借方本位币 | C11: 后端再次验证 | D11: 硬编码 + LLM复核 + 用户确认
A12: 凭证识别字段 | B12: ["凭证字号"] | C12: 后端再次验证 | D12: 硬编码 + LLM复核 + 用户确认
A13: 摘要 | B13: 摘要 | C13: 后端再次验证 | D13: 硬编码 + LLM复核 + 用户确认

Sheet TB字段映射
A1: 字段角色 | B1: 最终映射 | C1: 校验结果 | D1: 识别方式
A2: __balanceSelfSigned_closingForeign | B2: 否 | C2: 后端再次验证 | D2: 硬编码 + LLM复核 + 用户确认
A3: __balanceSelfSigned_closingFunctional | B3: 否 | C3: 后端再次验证 | D3: 硬编码 + LLM复核 + 用户确认
A4: __balanceSelfSigned_openingForeign | B4: 否 | C4: 后端再次验证 | D4: 硬编码 + LLM复核 + 用户确认
A5: __balanceSelfSigned_openingFunctional | B5: 否 | C5: 后端再次验证 | D5: 硬编码 + LLM复核 + 用户确认
A6: __signConvention | B6: unsigned | C6: 后端再次验证 | D6: 硬编码 + LLM复核 + 用户确认
A7: 科目编码 | B7: 科目编码 | C7: 后端再次验证 | D7: 硬编码 + LLM复核 + 用户确认
A8: 科目名称 | B8: ["科目名称"] | C8: 后端再次验证 | D8: 硬编码 + LLM复核 + 用户确认
A9: closingDirection | B9: 方向 | C9: 后端再次验证 | D9: 硬编码 + LLM复核 + 用户确认
A10: closingForeignAmount | B10: 期末余额(原币) | C10: 后端再次验证 | D10: 硬编码 + LLM复核 + 用户确认
A11: closingFunctionalAmount | B11: 期末余额(本位币) | C11: 后端再次验证 | D11: 硬编码 + LLM复核 + 用户确认
A12: 币种 | B12: 币种 | C12: 后端再次验证 | D12: 硬编码 + LLM复核 + 用户确认
... A17: ytdFunctionalDebit | B17: 本期发生借方(本位币) | C17: 后端再次验证 | D17: 硬编码 + LLM复核 + 用户确认

Sheet 数据质量

Sheet 待复核项目
A1: accounts | B1: 账面汇兑损益 | C1: 分类 | D1: 涉及币种 | E1: 日期 | F1: 识别证据 | G1: 汇兑损益科目 | H1: 待复核分路 | I1: 待复核原因 | J1: 当前分类（结构判定） | K1: 凭证匹配ID | L1: 凭证类型
A2: ["1002.01 人民币户","1123.02 预付款项-日元","6603.02 财务费用-汇兑损益"] | B2: 1200 | C2: 不构成汇兑事项 | D2: ["CNY","JPY"] | E2: 2026-03-13 | F2: 购汇日元预付日本供应商货款 | G2: ["6603.02 财务费用-汇兑损益"] | H2: 非货币性项目/异常复核 | I2: 对方科目为预付款、存货、固定资产等非货币性项目，不产生外币汇兑损益；账面汇差建议重分类复核 | J2: 不构成汇兑事项 | K2: 默认主体-2026-03-13-记-0041
A3: ["1002.01 人民币户","1123.02 预付款项-日元","6603.02 财务费用-汇兑损益"] | B3: 1200 | C3: 不构成汇兑事项 | D3: ["CNY","JPY"] | E3: 2026-06-13 | F3: 购汇日元预付日本供应商货款 | G3: ["6603.02 财务费用-汇兑损益"] | H3: 非货币性项目/异常复核 | I3: 对方科目为预付款、存货、固定资产等非货币性项目，不产生外币汇兑损益；账面汇差建议重分类复核 | J3: 不构成汇兑事项 | K3: 默认主体-2026-06-13-记-0094

Sheet 科目角色
A1: 字段角色 | B1: 最终映射 | C1: 校验结果 | D1: 识别方式
A2: 1002.01 人民币户 | B2: 货币性资产—货币资金 | C2: 后端再次验证 | D2: 硬编码 + LLM复核 + 用户确认
A3: 1002.02 美元户 | B3: 货币性资产—货币资金 | C3: 后端再次验证 | D3: 硬编码 + LLM复核 + 用户确认
A4: 1002.03 港币户 | B4: 货币性资产—货币资金 | C4: 后端再次验证 | D4: 硬编码 + LLM复核 + 用户确认
A5: 1122.01 应收账款-国内 | B5: 货币性资产—非货币资金 | C5: 后端再次验证 | D5: 硬编码 + LLM复核 + 用户确认
A6: 1122.02 应收账款-美元客户 | B6: 货币性资产—非货币资金 | C6: 后端再次验证 | D6: 硬编码 + LLM复核 + 用户确认
A7: 1122.03 应收账款-欧元客户 | B7: 货币性资产—非货币资金 | C7: 后端再次验证 | D7: 硬编码 + LLM复核 + 用户确认
A8: 1123.01 预付款项-国内 | B8: 非货币性项目 | C8: 后端再次验证 | D8: 硬编码 + LLM复核 + 用户确认
A9: 1123.02 预付款项-日元 | B9: 非货币性项目 | C9: 后端再次验证 | D9: 硬编码 + LLM复核 + 用户确认
A10: 1123.03 预付款项-美元 | B10: 非货币性项目 | C10: 后端再次验证 | D10: 硬编码 + LLM复核 + 用户确认
A11: 1405 库存商品 | B11: 非货币性项目 | C11: 后端再次验证 | D11: 硬编码 + LLM复核 + 用户确认
A12: 2202.01 应付账款-国内 | B12: 货币性负债 | C12: 后端再次验证 | D12: 硬编码 + LLM复核 + 用户确认
... A31: 6603.02 财务费用-汇兑损益 | B31: 汇兑损益 | C31: 后端再次验证 | D31: 硬编码 + LLM复核 + 用户确认

Sheet 央行汇率
A1: 每单位外币折合人民币 | B1: 币种 | C1: 汇率公布日期 | D1: 请求日期
A2: 7.0779 | B2: USD | C2: 2025-11-27 | D2: 2025-11-27
A3: 8.2056 | B3: EUR | C3: 2025-11-27 | D3: 2025-11-27
A4: 0.045267 | B4: JPY | C4: 2025-11-27 | D4: 2025-11-27
A5: 0.90998 | B5: HKD | C5: 2025-11-27 | D5: 2025-11-27
A6: 9.3671 | B6: GBP | C6: 2025-11-27 | D6: 2025-11-27
A7: 4.6134 | B7: AUD | C7: 2025-11-27 | D7: 2025-11-27
A8: 4.0339 | B8: NZD | C8: 2025-11-27 | D8: 2025-11-27
A9: 5.4565 | B9: SGD | C9: 2025-11-27 | D9: 2025-11-27
A10: 8.8005 | B10: CHF | C10: 2025-11-27 | D10: 2025-11-27
A11: 5.0378 | B11: CAD | C11: 2025-11-27 | D11: 2025-11-27
A12: 0.8828463 | B12: MOP | C12: 2025-11-27 | D12: 2025-11-27
A13: 1.7108933 | B13: MYR | C13: 2025-11-27 | D13: 2025-11-27
... A5617: 1 | B5617: CNY | C5617: 2026-06-30 | D5617: 2026-06-30

Sheet 汇率表
A1: 日期 | B1: AED | C1: AUD | D1: CAD | E1: CHF | F1: CNY | G1: DKK | H1: EUR | I1: GBP | J1: HKD | K1: HUF | L1: JPY | M1: KRW | N1: MOP | O1: MXN | P1: MYR | Q1: NOK | R1: NZD | S1: PLN | T1: RUB | U1: SAR | V1: SEK | W1: SGD | X1: THB | Y1: TRY | Z1: USD | AA1: ZAR
A2: 2025-11-27 | B2: 1.9256692 | C2: 4.6134 | D2: 5.0378 | E2: 8.8005 | F2: 1 | G2: 1.0986596 | H2: 8.2056 | I2: 9.3671 | J2: 0.90998 | K2: 0.021477894 | L2: 0.045267 | M2: 0.0048146365 | N2: 0.8828463 | O2: 0.38563881 | P2: 1.7108933 | Q2: 0.69352937 | R2: 4.0339 | S2: 1.9385856 | T2: 0.090088467 | U2: 1.8857962 | V2: 0.74526755 | W2: 5.4565 | X2: 0.21959682 | Y2: 0.16663862 | Z2: 7.0779 | AA2: 0.41272855
A3: 2025-11-28 | B3: 1.9268937 | C3: 4.6243 | D3: 5.046 | E3: 8.7971 | F3: 1 | G3: 1.0990219 | H3: 8.2078 | I3: 9.3697 | J3: 0.9099 | K3: 0.021522455 | L3: 0.045293 | M3: 0.0048360576 | N3: 0.88269044 | O3: 0.38583224 | P3: 1.7139723 | Q3: 0.69657286 | R3: 4.0533 | S3: 1.9417476 | T3: 0.090797657 | U3: 1.8865077 | V3: 0.74710497 | W3: 5.4589 | X3: 0.2196547 | Y3: 0.16657422 | Z3: 7.0789 | AA3: 0.41262637
A4: 2025-11-29 | B4: 1.9268937 | C4: 4.6243 | D4: 5.046 | E4: 8.7971 | F4: 1 | G4: 1.0990219 | H4: 8.2078 | I4: 9.3697 | J4: 0.9099 | K4: 0.021522455 | L4: 0.045293 | M4: 0.0048360576 | N4: 0.88269044 | O4: 0.38583224 | P4: 1.7139723 | Q4: 0.69657286 | R4: 4.0533 | S4: 1.9417476 | T4: 0.090797657 | U4: 1.8865077 | V4: 0.74710497 | W4: 5.4589 | X4: 0.2196547 | Y4: 0.16657422 | Z4: 7.0789 | AA4: 0.41262637
A5: 2025-11-30 | B5: 1.9268937 | C5: 4.6243 | D5: 5.046 | E5: 8.7971 | F5: 1 | G5: 1.0990219 | H5: 8.2078 | I5: 9.3697 | J5: 0.9099 | K5: 0.021522455 | L5: 0.045293 | M5: 0.0048360576 | N5: 0.88269044 | O5: 0.38583224 | P5: 1.7139723 | Q5: 0.69657286 | R5: 4.0533 | S5: 1.9417476 | T5: 0.090797657 | U5: 1.8865077 | V5: 0.74710497 | W5: 5.4589 | X5: 0.2196547 | Y5: 0.16657422 | Z5: 7.0789 | AA5: 0.41262637
A6: 2025-12-01 | B6: 1.9255209 | C6: 4.6302 | D6: 5.0621 | E6: 8.8013 | F6: 1 | G6: 1.0985389 | H6: 8.2052 | I6: 9.3616 | J6: 0.90877 | K6: 0.021500568 | L6: 0.045331 | M6: 0.0048192771 | N6: 0.88160099 | O6: 0.38678734 | P6: 1.7125927 | Q6: 0.69920291 | R6: 4.0535 | S6: 1.9374588 | T6: 0.091256696 | U6: 1.8854051 | V6: 0.74850299 | W6: 5.4569 | X6: 0.22010917 | Y6: 0.16644834 | Z6: 7.0759 | AA6: 0.41324022
A7: 2025-12-02 | B7: 1.9262998 | C7: 4.6292 | D7: 5.0539 | E7: 8.7915 | F7: 1 | G7: 1.0995052 | H7: 8.2113 | I7: 9.3451 | J7: 0.9088 | K7: 0.021563714 | L7: 0.045495 | M7: 0.0048095421 | N7: 0.88191199 | O7: 0.38647343 | P7: 1.7131208 | Q7: 0.69837279 | R7: 4.0512 | S7: 1.942351 | T7: 0.091027427 | U7: 1.8849786 | V7: 0.74833495 | W7: 5.4576 | X7: 0.22106287 | Y7: 0.16668722 | Z7: 7.0794 | AA7: 0.41399296
A8: 2025-12-03 | B8: 1.9245944 | C8: 4.6437 | D8: 5.0589 | E8: 8.8047 | F8: 1 | G8: 1.1004732 | H8: 8.221 | I8: 9.3429 | J8: 0.90897 | K8: 0.021577254 | L8: 0.04536 | M8: 0.0048144047 | N8: 0.88214538 | O8: 0.38677238 | P8: 1.7116547 | Q8: 0.69793412 | R8: 4.0567 | S8: 1.9417476 | T8: 0.091262526 | U8: 1.8830973 | V8: 0.74985003 | W8: 5.4544 | X8: 0.22092124 | Y8: 0.16641759 | Z8: 7.0754 | AA8: 0.41312071
A9: 2025-12-04 | B9: 1.9215618 | C9: 4.6586 | D9: 5.0597 | E9: 8.8252 | F9: 1 | G9: 1.1025358 | H9: 8.2373 | I9: 9.4207 | J9: 0.90891 | K9: 0.021635843 | L9: 0.045468 | M9: 0.0048139412 | N9: 0.88198977 | O9: 0.38608548 | P9: 1.7142074 | Q9: 0.70126227 | R9: 4.0715 | S9: 1.9498499 | T9: 0.091377609 | U9: 1.8808306 | V9: 0.75284198 | W9: 5.4573 | X9: 0.22134667 | Y9: 0.16629915 | Z9: 7.0733 | AA9: 0.41430169
A10: 2025-12-05 | B10: 1.9258917 | C10: 4.6754 | D10: 5.0682 | E10: 8.8016 | F10: 1 | G10: 1.102779 | H10: 8.2376 | I10: 9.4269 | J10: 0.90906 | K10: 0.021508198 | L10: 0.045597 | M10: 0.0047991553 | N10: 0.88261253 | O10: 0.38791264 | P10: 1.7198383 | Q10: 0.6993007 | R10: 4.0767 | S10: 1.9453361 | T10: 0.092223698 | U10: 1.8847654 | V10: 0.7505817 | W10: 5.4573 | X10: 0.22079442 | Y10: 0.16645139 | Z10: 7.0749 | AA10: 0.41637174
A11: 2025-12-06 | B11: 1.9258917 | C11: 4.6754 | D11: 5.0682 | E11: 8.8016 | F11: 1 | G11: 1.102779 | H11: 8.2376 | I11: 9.4269 | J11: 0.90906 | K11: 0.021508198 | L11: 0.045597 | M11: 0.0047991553 | N11: 0.88261253 | O11: 0.38791264 | P11: 1.7198383 | Q11: 0.6993007 | R11: 4.0767 | S11: 1.9453361 | T11: 0.092223698 | U11: 1.8847654 | V11: 0.7505817 | W11: 5.4573 | X11: 0.22079442 | Y11: 0.16645139 | Z11: 7.0749 | AA11: 0.41637174
A12: 2025-12-07 | B12: 1.9258917 | C12: 4.6754 | D12: 5.0682 | E12: 8.8016 | F12: 1 | G12: 1.102779 | H12: 8.2376 | I12: 9.4269 | J12: 0.90906 | K12: 0.021508198 | L12: 0.045597 | M12: 0.0047991553 | N12: 0.88261253 | O12: 0.38791264 | P12: 1.7198383 | Q12: 0.6993007 | R12: 4.0767 | S12: 1.9453361 | T12: 0.092223698 | U12: 1.8847654 | V12: 0.7505817 | W12: 5.4573 | X12: 0.22079442 | Y12: 0.16645139 | Z12: 7.0749 | AA12: 0.41637174
A13: 2025-12-08 | B13: 1.9258917 | C13: 4.6954 | D13: 5.1153 | E13: 8.7914 | F13: 1 | G13: 1.102779 | H13: 8.2374 | I13: 9.4271 | J13: 0.90919 | K13: 0.021581771 | L13: 0.045563 | M13: 0.0048051511 | N13: 0.8822232 | O13: 0.38919592 | P13: 1.720075 | Q13: 0.6997411 | R13: 4.0861 | S13: 1.9476852 | T13: 0.092470155 | U13: 1.8846234 | V13: 0.75261534 | W13: 5.4599 | X13: 0.22161647 | Y13: 0.16623418 | Z13: 7.0764 | AA13: 0.41771094
... A217: 2026-06-30 | B217: 1.8510634 | C217: 4.6804 | D217: 4.7847 | E217: 8.4228 | F217: 1 | G217: 1.039177 | H217: 7.7671 | I217: 9.0145 | J217: 0.86855 | K217: 0.021961177 | L217: 0.042045 | M217: 0.0044029588 | N217: 0.84324142 | O217: 0.38968124 | P217: 1.6734161 | Q217: 0.68493151 | R217: 3.8414 | S217: 1.8121195 | T217: 0.088266707 | U217: 1.8103807 | V217: 0.70032915 | W217: 5.2605 | X217: 0.20424419 | Y217: 0.14580788 | Z217: 6.8109 | AA217: 0.41440471

Sheet 异常与限制

Sheet _rate_snapshot
A1: 项目 | B1: 内容
A2: 汇率快照结束日 | B2: 2026-06-30
A3: 汇率抓取时间 | B3: 2026-09-29T08:15:50.976302300+00:00
A4: 缺失币种/日期 | B4: []
